<?xml version="1.0" encoding="utf-8"?>
<!-- This URDF was automatically created by SolidWorks to URDF Exporter! Originally created by Stephen Brawner (brawner@gmail.com) 
     Commit Version: 1.6.0-4-g7f85cfe  Build Version: 1.6.7995.38578
     For more information, please see http://wiki.ros.org/sw_urdf_exporter -->
<robot
  name="right_arm_description">
  <link
    name="right_base_link">
    <inertial>
      <origin
        xyz="0.00017935 -0.0018838 0.038665"
        rpy="0 0 0" />
       <mass
        value="1.22564018" />
      <inertia
        ixx="0.00301289"
        ixy="-0.00000023"
        ixz="-0.00002258"
        iyy="0.00309754"
        iyz="0.00003044"
        izz="0.00147750" />
    </inertial>
    <visual>
      <origin
        xyz="0 0 0"
        rpy="0 0 0" />
      <geometry>
        <mesh
          filename="package://right_arm_description/meshes/right_base_link.STL" />
      </geometry>
      <material
        name="">
        <color
          rgba="0.79216 0.81961 0.93333 1" />
      </material>
    </visual>
    <collision>
      <origin
        xyz="0 0 0"
        rpy="0 0 0" />
      <geometry>
        <mesh
          filename="package://right_arm_description/meshes/right_base_link.STL" />
      </geometry>
    </collision>
  </link>
  <link
    name="right_link_1">
    <inertial>
      <origin
        xyz="-0.0010955 -0.0015843 -0.0049495"
        rpy="0 0 0" />
      <mass
        value="1.33502383" />
      <inertia
        ixx="0.00145723"
        ixy="-0.00000490"
        ixz="-0.00007253"
        iyy="0.00222607"
        iyz="-0.00003039"
        izz="0.00135878" />
    </inertial>
    <visual>
      <origin
        xyz="0 0 0"
        rpy="0 0 3.1416" />
      <geometry>
        <mesh
          filename="package://right_arm_description/meshes/right_link_1.STL" />
      </geometry>
      <material
        name="">
        <color
          rgba="0.79216 0.81961 0.93333 1" />
      </material>
    </visual>
    <collision>
      <origin
        xyz="0 0 0"
        rpy="0 0 0" />
      <geometry>
        <mesh
          filename="package://right_arm_description/meshes/right_link_1.STL" />
      </geometry>
    </collision>
  </link>
  <joint
    name="right_joint_0"
    type="revolute">
    <origin
      xyz="0 0 0.1355"
      rpy="0 0 3.1416" />
    <parent
      link="right_base_link" />
    <child
      link="right_link_1" />
    <axis
      xyz="0 0 -1" />
    <limit
      lower="-2.8798"
      upper="2.3562"
      effort="40"
      velocity="10.472" />
    <dynamics
      damping="0.1"
      friction="0.1" />
  </joint>
  <link
    name="right_link_2">
    <inertial>
      <origin
        xyz="0.00050822 0.044928 -0.020626"
        rpy="0 0 0" />
      <mass
        value="0.18252313" />
      <inertia
        ixx="0.00061618"
        ixy="-0.00000304"
        ixz="0.00000280"
        iyy="0.00015993"
        iyz="0.00009588"
        izz="0.00050408" />
    </inertial>
    <visual>
      <origin
        xyz="0 0 0"
        rpy="0 0 0" />
      <geometry>
        <mesh
          filename="package://right_arm_description/meshes/right_link_2.STL" />
      </geometry>
      <material
        name="">
        <color
          rgba="0.79216 0.81961 0.93333 1" />
      </material>
    </visual>
    <collision>
      <origin
        xyz="0 0 0"
        rpy="0 0 0" />
      <geometry>
        <mesh
          filename="package://right_arm_description/meshes/right_link_2.STL" />
      </geometry>
    </collision>
  </link>
  <joint
    name="right_joint_1"
    type="revolute">
    <origin
      xyz="0 0 0"
      rpy="1.5708 -1.5708 0" />
    <parent
      link="right_link_1" />
    <child
      link="right_link_2" />
    <axis
      xyz="0 0 -1" />
    <limit
      lower="-0.3491"
      upper="3.0543"
      effort="40"
      velocity="10.472" />
    <dynamics
      damping="0.1"
      friction="0.1" />
  </joint>
  <link
    name="right_link_3">
    <inertial>
      <origin
        xyz="3.1902E-07 0.00060542 0.054984"
        rpy="0 0 0" />
      <mass
        value="1.04367487" />
      <inertia
        ixx="0.00604989"
        ixy="0.00000106"
        ixz="0.00001728"
        iyy="0.00604509"
        iyz="-0.00000298"
        izz="0.00052741" />
    </inertial>
    <visual>
      <origin
        xyz="0 0 0"
        rpy="0 0 0" />
      <geometry>
        <mesh
          filename="package://right_arm_description/meshes/right_link_3.STL" />
      </geometry>
      <material
        name="">
        <color
          rgba="0.79216 0.81961 0.93333 1" />
      </material>
    </visual>
    <collision>
      <origin
        xyz="0 0 0"
        rpy="0 0 0" />
      <geometry>
        <mesh
          filename="package://right_arm_description/meshes/right_link_3.STL" />
      </geometry>
    </collision>
  </link>
  <joint
    name="right_joint_2"
    type="revolute">
    <origin
      xyz="0 0.20975 0"
      rpy="1.5708 1.5708 0" />
    <parent
      link="right_link_2" />
    <child
      link="right_link_3" />
    <axis
      xyz="0 0 -1" />
    <limit
      lower="-2.5307"
      upper="2.5307"
      effort="27"
      velocity="3.7699" />
    <dynamics
      damping="0.1"
      friction="0.1" />
  </joint>
  <link
    name="right_link_4">
    <inertial>
      <origin
        xyz="0.0001104 0.067007 0.00094041"
        rpy="0 0 0" />
      <mass
        value="0.57070674" />
      <inertia
        ixx="0.00349959"
        ixy="-0.00000396"
        ixz="0.00000024"
        iyy="0.00035327"
        iyz="-0.00000066"
        izz="0.00340757" />
    </inertial>
    <visual>
      <origin
        xyz="0 0 0"
        rpy="0 0 0" />
      <geometry>
        <mesh
          filename="package://right_arm_description/meshes/right_link_4.STL" />
      </geometry>
      <material
        name="">
        <color
          rgba="0.79216 0.81961 0.93333 1" />
      </material>
    </visual>
    <collision>
      <origin
        xyz="0 0 0"
        rpy="0 0 0" />
      <geometry>
        <mesh
          filename="package://right_arm_description/meshes/right_link_4.STL" />
      </geometry>
    </collision>
  </link>
  <joint
    name="right_joint_3"
    type="revolute">
    <origin
      xyz="0 0 0"
      rpy="-1.5708 0 0" />
    <parent
      link="right_link_3" />
    <child
      link="right_link_4" />
    <axis
      xyz="0 0 -1" />
    <limit
      lower="-2.0944"
      upper="1.5708"
      effort="27"
      velocity="3.7699" />
    <dynamics
      damping="0.1"
      friction="0.1" />
  </joint>
  <link
    name="right_link_5">
    <inertial>
      <origin
        xyz="0.00030568 -0.0011178 0.084532"
        rpy="0 0 0" />
      <mass
        value="0.66175571" />
      <inertia
        ixx="0.00533902"
        ixy="0.00000486"
        ixz="-0.00001590"
        iyy="0.00526534"
        iyz="0.00006056"
        izz="0.00045833" />
    </inertial>
    <visual>
      <origin
        xyz="0 0 0"
        rpy="0 0 0" />
      <geometry>
        <mesh
          filename="package://right_arm_description/meshes/right_link_5.STL" />
      </geometry>
      <material
        name="">
        <color
          rgba="0.79216 0.81961 0.93333 1" />
      </material>
    </visual>
    <collision>
      <origin
        xyz="0 0 0"
        rpy="0 0 0" />
      <geometry>
        <mesh
          filename="package://right_arm_description/meshes/right_link_5.STL" />
      </geometry>
    </collision>
  </link>
  <joint
    name="right_joint_4"
    type="revolute">
    <origin
      xyz="0 0.24 0"
      rpy="1.5708 0 0" />
    <parent
      link="right_link_4" />
    <child
      link="right_link_5" />
    <axis
      xyz="0 0 -1" />
    <limit
      lower="-2.5307"
      upper="2.5307"
      effort="7"
      velocity="12.566" />
    <dynamics
      damping="0.1"
      friction="0.1" />
  </joint>
  <link
    name="right_link_6">
    <inertial>
      <origin
        xyz="0.0010926 -0.00047974 -0.0001482"
        rpy="0 0 0" />
      <mass
        value="0.41299783" />
      <inertia
        ixx="0.00019636"
        ixy="0.00000521"
        ixz="-0.00000127"
        iyy="0.00019157"
        iyz="0.00000008"
        izz="0.00019007" />
    </inertial>
    <visual>
      <origin
        xyz="0 0 0"
        rpy="0 0 0" />
      <geometry>
        <mesh
          filename="package://right_arm_description/meshes/right_link_6.STL" />
      </geometry>
      <material
        name="">
        <color
          rgba="0.79216 0.81961 0.93333 1" />
      </material>
    </visual>
    <collision>
      <origin
        xyz="0 0 0"
        rpy="0 0 0" />
      <geometry>
        <mesh
          filename="package://right_arm_description/meshes/right_link_6.STL" />
      </geometry>
    </collision>
  </link>
  <joint
    name="right_joint_5"
    type="revolute">
    <origin
      xyz="0 0 0"
      rpy="1.5708 0 3.1416" />
    <parent
      link="right_link_5" />
    <child
      link="right_link_6" />
    <axis
      xyz="0 0 -1" />
    <limit
      lower="-0.6981"
      upper="0.6981"
      effort="7"
      velocity="12.566" />
    <dynamics
      damping="0.1"
      friction="0.1" />
  </joint>
  <link
    name="right_link_7">
    <inertial>
      <origin
        xyz="-5.5511E-17 0.028684 0.0037068"
        rpy="0 0 0" />
      <mass
        value="0.19263144" />
      <inertia
        ixx="0.00048701"
        ixy="0.00000000"
        ixz="0.00000000"
        iyy="0.00020494"
        iyz="0.00000118"
        izz="0.00032740" />
    </inertial>
    <visual>
      <origin
        xyz="0 0 0"
        rpy="0 0 0" />
      <geometry>
        <mesh
          filename="package://right_arm_description/meshes/right_link_7.STL" />
      </geometry>
      <material
        name="">
        <color
          rgba="0.79216 0.81961 0.93333 1" />
      </material>
    </visual>
    <collision>
      <origin
        xyz="0 0 0"
        rpy="0 0 0" />
      <geometry>
        <mesh
          filename="package://right_arm_description/meshes/right_link_7.STL" />
      </geometry>
    </collision>
  </link>
  <joint
    name="right_joint_6"
    type="revolute">
    <origin
      xyz="0 0 0"
      rpy="0 -1.5708 -3.1416" />
    <parent
      link="right_link_6" />
    <child
      link="right_link_7" />
    <axis
      xyz="0 0 -1" />
    <limit
      lower="-1.5708"
      upper="1.5708"
      effort="7"
      velocity="12.566" />
    <dynamics
      damping="0.1"
      friction="0.1" />
  </joint>
  <link
    name="attachment_point" />
  <joint
    name="right_attachment_fixed_joint"
    type="fixed">
    <origin
      xyz="0 0.06 0"
      rpy="-1.5708 -3.1416 0" />
    <parent
      link="right_link_7" />
    <child
      link="attachment_point" />
  </joint>
</robot>