<?xml version="1.0" encoding="utf-8"?>
<!-- This URDF was automatically created by SolidWorks to URDF Exporter! Originally created by Stephen Brawner (brawner@gmail.com) 
     Commit Version: 1.6.0-4-g7f85cfe  Build Version: 1.6.7995.38578
     For more information, please see http://wiki.ros.org/sw_urdf_exporter -->
<robot
  name="left_arm_description">
  <link
    name="left_base_link">
    <inertial>
      <origin
        xyz="0.00017935 0.0018838 0.038665"
        rpy="0 0 0" />
      <mass
        value="1.22564" />
      <inertia
        ixx="0.00256728"
        ixy="0.00000020"
        ixz="-0.00002190"
        iyy="0.00265135"
        iyz="-0.00003114"
        izz="0.00082058" />
    </inertial>
    <visual>
      <origin
        xyz="0 0 0"
        rpy="0 0 0" />
      <geometry>
        <mesh
          filename="package://left_arm_description/meshes/left_base_link.STL" />
      </geometry>
      <material
        name="">
        <color
          rgba="0.79216 0.81961 0.93333 1" />
      </material>
    </visual>
    <collision>
      <origin
        xyz="0 0 0"
        rpy="0 0 0" />
      <geometry>
        <mesh
          filename="package://left_arm_description/meshes/left_base_link.STL" />
      </geometry>
    </collision>
  </link>
  <link
    name="left_link_1">
    <inertial>
      <origin
        xyz="-0.00109529335918426 0.00158432100362189 -0.00494979473059115"
        rpy="0 0 0" />
      <mass
        value="1.33500720" />
      <inertia
        ixx="0.00101162"
        ixy="0.00000422"
        ixz="-0.00007250"
        iyy="0.00156912"
        iyz="0.00002970"
        izz="0.00091256" />
    </inertial>
    <visual>
      <origin
        xyz="0 0 0"
        rpy="0 0 0" />
      <geometry>
        <mesh
          filename="package://left_arm_description/meshes/left_link_1.STL" />
      </geometry>
      <material
        name="">
        <color
          rgba="0.792156862745098 0.819607843137255 0.933333333333333 1" />
      </material>
    </visual>
    <collision>
      <origin
        xyz="0 0 0"
        rpy="0 0 0" />
      <geometry>
        <mesh
          filename="package://left_arm_description/meshes/left_link_1.STL" />
      </geometry>
    </collision>
  </link>
  <joint
    name="left_joint_0"
    type="revolute">
    <origin
      xyz="0 0 0.1355"
      rpy="0 0 0" />
    <parent
      link="left_base_link" />
    <child
      link="left_link_1" />
    <axis
      xyz="0 0 -1" />
    <limit
      lower="-2.3562"
      upper="2.8798"
      effort="40"
      velocity="10.472" />
    <dynamics
      damping="0.1"
      friction="0.1" />
  </joint>
  <link
    name="left_link_2">
    <inertial>
      <origin
        xyz="0.000508224298191348 -0.0449280282138882 -0.0206256236163859"
        rpy="0 0 0" />
      <mass
        value="0.18252313" />
      <inertia
        ixx="0.00061618"
        ixy="0.00000304"
        ixz="0.00000280"
        iyy="0.000159935"
        iyz="-0.00009588"
        izz="0.00050408" />
    </inertial>
    <visual>
      <origin
        xyz="0 0 0"
        rpy="0 0 0" />
      <geometry>
        <mesh
          filename="package://left_arm_description/meshes/left_link_2.STL" />
      </geometry>
      <material
        name="">
        <color
          rgba="0.792156862745098 0.819607843137255 0.933333333333333 1" />
      </material>
    </visual>
    <collision>
      <origin
        xyz="0 0 0"
        rpy="0 0 0" />
      <geometry>
        <mesh
          filename="package://left_arm_description/meshes/left_link_2.STL" />
      </geometry>
    </collision>
  </link>
  <joint
    name="left_joint_1"
    type="revolute">
    <origin
      xyz="0 0 0"
      rpy="1.5708 -1.5708 0" />
    <parent
      link="left_link_1" />
    <child
      link="left_link_2" />
    <axis
      xyz="0 0 -1" />
    <limit
      lower="-3.0513"
      upper="0.3491"
      effort="40"
      velocity="10.472" />
    <dynamics
      damping="0.1"
      friction="0.1" />
  </joint>
  <link
    name="left_link_3">
    <inertial>
      <origin
        xyz="2.83802482036803E-07 -0.000605505330037032 0.054984322701974"
        rpy="0 0 0" />
      <mass
        value="1.04367671" />
      <inertia
        ixx="0.00584704"
        ixy="-0.00000039"
        ixz="0.00001725"
        iyy="0.00583635"
        iyz="0.00000341"
        izz="0.00032818" />
    </inertial>
    <visual>
      <origin
        xyz="0 0 0"
        rpy="0 0 0" />
      <geometry>
        <mesh
          filename="package://left_arm_description/meshes/left_link_3.STL" />
      </geometry>
      <material
        name="">
        <color
          rgba="0.792156862745098 0.819607843137255 0.933333333333333 1" />
      </material>
    </visual>
    <collision>
      <origin
        xyz="0 0 0"
        rpy="0 0 0" />
      <geometry>
        <mesh
          filename="package://left_arm_description/meshes/left_link_3.STL" />
      </geometry>
    </collision>
  </link>
  <joint
    name="left_joint_2"
    type="revolute">
    <origin
      xyz="0 -0.20975 0"
      rpy="0 1.5708 1.5708" />
    <parent
      link="left_link_2" />
    <child
      link="left_link_3" />
    <axis
      xyz="0 0 -1" />
    <limit
      lower="-2.5307"
      upper="2.5307"
      effort="27"
      velocity="3.77" />
    <dynamics
      damping="0.1"
      friction="0.1" />
  </joint>
  <link
    name="left_link_4">
    <inertial>
      <origin
        xyz="0.000110401234317883 -0.0670069142247546 0.000940172282106119"
        rpy="0 0 0" />
      <mass
        value="0.57070680" />
      <inertia
        ixx="0.00349959"
        ixy="0.00000396"
        ixz="0.00000024"
        iyy="0.00035327"
        iyz="0.00000065"
        izz="0.00340757" />
    </inertial>
    <visual>
      <origin
        xyz="0 0 0"
        rpy="0 0 0" />
      <geometry>
        <mesh
          filename="package://left_arm_description/meshes/left_link_4.STL" />
      </geometry>
      <material
        name="">
        <color
          rgba="0.792156862745098 0.819607843137255 0.933333333333333 1" />
      </material>
    </visual>
    <collision>
      <origin
        xyz="0 0 0"
        rpy="0 0 0" />
      <geometry>
        <mesh
          filename="package://left_arm_description/meshes/left_link_4.STL" />
      </geometry>
    </collision>
  </link>
  <joint
    name="left_joint_3"
    type="revolute">
    <origin
      xyz="0 0 0"
      rpy="1.5708 0 0" />
    <parent
      link="left_link_3" />
    <child
      link="left_link_4" />
    <axis
      xyz="0 0 1" />
    <limit
      lower="-2.0944"
      upper="1.4835"
      effort="27"
      velocity="3.77" />
    <dynamics
      damping="0.1"
      friction="0.1" />
  </joint>
  <link
    name="left_link_5">
    <inertial>
      <origin
        xyz="0.000305709664333387 0.00111778275538414 0.08453196488493"
        rpy="0 0 0" />
      <mass
        value="0.66041024" />
      <inertia
        ixx="0.00532998"
        ixy="-0.00000485"
        ixz="-0.00001587"
        iyy="0.00525652"
        iyz="-0.00005887"
        izz="0.00045790" />
    </inertial>
    <visual>
      <origin
        xyz="0 0 0"
        rpy="0 0 0" />
      <geometry>
        <mesh
          filename="package://left_arm_description/meshes/left_link_5.STL" />
      </geometry>
      <material
        name="">
        <color
          rgba="0.792156862745098 0.819607843137255 0.933333333333333 1" />
      </material>
    </visual>
    <collision>
      <origin
        xyz="0 0 0"
        rpy="0 0 0" />
      <geometry>
        <mesh
          filename="package://left_arm_description/meshes/left_link_5.STL" />
      </geometry>
    </collision>
  </link>
  <joint
    name="left_joint_4"
    type="revolute">
    <origin
      xyz="0 -0.24 0"
      rpy="-1.5707963267949 0 0" />
    <parent
      link="left_link_4" />
    <child
      link="left_link_5" />
    <axis
      xyz="0 0 -1" />
    <limit
      lower="-2.5307"
      upper="2.5307"
      effort="7"
      velocity="12.566" />
    <dynamics
      damping="0.1"
      friction="0.1" />
  </joint>
  <link
    name="left_link_6">
    <inertial>
      <origin
        xyz="-0.00109259369146801 -0.000479735518615576 -0.000148198512131464"
        rpy="0 0 0" />
      <mass
        value="0.41299778" />
      <inertia
        ixx="0.00019636"
        ixy="-0.00000521"
        ixz="0.00000127"
        iyy="0.00019157"
        iyz="0.00000008"
        izz="0.00019007" />
    </inertial>
    <visual>
      <origin
        xyz="0 0 0"
        rpy="0 0 0" />
      <geometry>
        <mesh
          filename="package://left_arm_description/meshes/left_link_6.STL" />
      </geometry>
      <material
        name="">
        <color
          rgba="0.792156862745098 0.819607843137255 0.933333333333333 1" />
      </material>
    </visual>
    <collision>
      <origin
        xyz="0 0 0"
        rpy="0 0 0" />
      <geometry>
        <mesh
          filename="package://left_arm_description/meshes/left_link_6.STL" />
      </geometry>
    </collision>
  </link>
  <joint
    name="left_joint_5"
    type="revolute">
    <origin
      xyz="0 0 0"
      rpy="1.5708 0 0" />
    <parent
      link="left_link_5" />
    <child
      link="left_link_6" />
    <axis
      xyz="0 0 1" />
    <limit
      lower="-0.6981"
      upper="0.6981"
      effort="7"
      velocity="12.566" />
    <dynamics
      damping="0.1"
      friction="0.1" />
  </joint>
  <link
    name="left_link_7">
    <inertial>
      <origin
        xyz="0.0286842428588672 6.10622663543836E-16 0.00370678756780378"
        rpy="0 0 0" />
      <mass
        value="0.19263144" />
      <inertia
        ixx="0.00020494"
        ixy="0.00000000"
        ixz="0.00000118"
        iyy="0.00048701"
        iyz="0.00000000"
        izz="0.00032740" />
    </inertial>
    <visual>
      <origin
        xyz="0 0 0"
        rpy="0 0 0" />
      <geometry>
        <mesh
          filename="package://left_arm_description/meshes/left_link_7.STL" />
      </geometry>
      <material
        name="">
        <color
          rgba="0.792156862745098 0.819607843137255 0.933333333333333 1" />
      </material>
    </visual>
    <collision>
      <origin
        xyz="0 0 0"
        rpy="0 0 0" />
      <geometry>
        <mesh
          filename="package://left_arm_description/meshes/left_link_7.STL" />
      </geometry>
    </collision>
  </link>
  <joint
    name="left_joint_6"
    type="revolute">
    <origin
      xyz="0 0 0"
      rpy="1.5708 0 -1.5708" />
    <parent
      link="left_link_6" />
    <child
      link="left_link_7" />
    <axis
      xyz="0 0 -1" />
    <limit
      lower="-1.5708"
      upper="1.5708"
      effort="7"
      velocity="12.566" />
    <dynamics
      damping="0.1"
      friction="0.1" />
  </joint>
  <link
    name="attachment_point" />
  <joint
    name="left_attachment_fixed_joint"
    type="fixed">
    <origin
      xyz="0.06 0 0"
      rpy="1.5708 0 1.5708" />
    <parent
      link="left_link_7" />
    <child
      link="attachment_point" />
  </joint>
</robot>