<?xml version="1.0" encoding="utf-8"?>
<!-- This URDF was automatically created by SolidWorks to URDF Exporter! Originally created by Stephen Brawner (brawner@gmail.com) 
     Commit Version: 1.6.0-4-g7f85cfe  Build Version: 1.6.7995.38578
     For more information, please see http://wiki.ros.org/sw_urdf_exporter -->
<robot
  name="gripper_description">
  <link
    name="gripper_base_link">
    <inertial>
      <origin
        xyz="1.1802E-06 6.1128E-05 0.030778"
        rpy="0 0 0" />
      <mass
        value="0.35269004" />
      <inertia
        ixx="0.00042406"
        ixy="0.00000026"
        ixz="0.00000000"
        iyy="0.00047612"
        iyz="-0.00000006"
        izz="0.00018806" />
    </inertial>
    <visual>
      <origin
        xyz="0 0 0"
        rpy="0 0 0" />
      <geometry>
        <mesh
          filename="package://gripper_description/meshes/gripper_base_link.STL" />
      </geometry>
      <material
        name="">
        <color
          rgba="0.79216 0.81961 0.93333 1" />
      </material>
    </visual>
    <collision>
      <origin
        xyz="0 0 0"
        rpy="0 0 0" />
      <geometry>
        <mesh
          filename="package://gripper_description/meshes/gripper_base_link.STL" />
      </geometry>
    </collision>
  </link>
  <link
    name="right_finger">
    <inertial>
      <origin
        xyz="0.0034569 0.0014257 -0.003385"
        rpy="0 0 0" />
      <mass
        value="0.04503966" />
      <inertia
        ixx="0.00002075"
        ixy="-0.00000178"
        ixz="0.00000138"
        iyy="0.00002763"
        iyz="0.00000178"
        izz="0.00001805" />
    </inertial>
    <visual>
      <origin
        xyz="0 0 0"
        rpy="0 0 0" />
      <geometry>
        <mesh
          filename="package://gripper_description/meshes/right_finger.STL" />
      </geometry>
      <material
        name="">
        <color
          rgba="0.79216 0.81961 0.93333 1" />
      </material>
    </visual>
    <collision>
      <origin
        xyz="0 0 0"
        rpy="0 0 0" />
      <geometry>
        <mesh
          filename="package://gripper_description/meshes/right_finger.STL" />
      </geometry>
    </collision>
  </link>
  <joint
    name="right_finger_joint"
    type="prismatic">
    <origin
      xyz="-0.065 0 0.079"
      rpy="0 0 0" />
    <parent
      link="gripper_base_link" />
    <child
      link="right_finger" />
    <axis
      xyz="1 0 0" />
    <limit
      lower="0"
      upper="0.045"
      effort="80"
      velocity="0.125" />
    <dynamics
      damping="0.1"
      friction="0.1" />
  </joint>
  <link
    name="left_finger">
    <inertial>
      <origin
        xyz="-0.0034569 -0.0014257 -0.003385"
        rpy="0 0 0" />
      <mass
        value="0.04503966" />
      <inertia
        ixx="0.00002075"
        ixy="-0.00000178"
        ixz="-0.00000138"
        iyy="0.00002763"
        iyz="-0.00000178"
        izz="0.00001805" />
    </inertial>
    <visual>
      <origin
        xyz="0 0 0"
        rpy="0 0 0" />
      <geometry>
        <mesh
          filename="package://gripper_description/meshes/left_finger.STL" />
      </geometry>
      <material
        name="">
        <color
          rgba="0.79216 0.81961 0.93333 1" />
      </material>
    </visual>
    <collision>
      <origin
        xyz="0 0 0"
        rpy="0 0 0" />
      <geometry>
        <mesh
          filename="package://gripper_description/meshes/left_finger.STL" />
      </geometry>
    </collision>
  </link>
  <joint
    name="left_finger_joint"
    type="prismatic">
    <origin
      xyz="0.065 0 0.079"
      rpy="0 0 0" />
    <parent
      link="gripper_base_link" />
    <child
      link="left_finger" />
    <axis
      xyz="-1 0 0" />
    <limit
      lower="0"
      upper="0.045"
      effort="80"
      velocity="0.125" />
    <dynamics
      damping="0.1"
      friction="0.1" />
    <mimic joint="right_finger_joint" multiplier="1" offset="0"/>
  </joint>
</robot>