<mujoco model="dual_arm_robot">
  
  <compiler angle="radian" meshdir="../meshes/" balanceinertia="true" />
  
  
  
  <option timestep="0.001" integrator="implicitfast" gravity="0 0 -9.81" iterations="50" ls_iterations="20" solver="Newton">
    <flag contact="enable" energy="enable" />
  </option>

  
  <visual>
    <headlight ambient="0.4 0.4 0.4" diffuse="0.6 0.6 0.6" specular="0.1 0.1 0.1" />
    <rgba haze="0.15 0.25 0.35 1" />
    <quality shadowsize="0" />
  </visual>

  <statistic extent="2" center="0 0 1" />

  <asset>
    <texture type="skybox" builtin="gradient" rgb1="0.3 0.5 0.7" rgb2="0 0 0" width="512" height="3072" />
    <texture type="2d" name="groundplane" builtin="checker" mark="edge" rgb1="0.2 0.3 0.4" rgb2="0.1 0.2 0.3" markrgb="0.8 0.8 0.8" width="300" height="300" />
    <material name="groundplane" texture="groundplane" texuniform="true" texrepeat="5 5" reflectance="0" />
    
    <mesh name="base_link" file="base_link.STL" />
    <mesh name="left_arm_attachment_point" file="left_arm_attachment_point.STL" />
    <mesh name="right_arm_attachment_point" file="right_arm_attachment_point.STL" />
    <mesh name="left_base_link" file="left_base_link.STL" />
    <mesh name="left_base_link_col" file="collision/left_base_link.STL" />
    <mesh name="left_link_1" file="left_link_1.STL" />
    <mesh name="left_link_1_col" file="collision/left_link_1.STL" />
    <mesh name="left_link_2" file="left_link_2.STL" />
    <mesh name="left_link_2_col" file="collision/left_link_2.STL" />
    <mesh name="left_link_3" file="left_link_3.STL" />
    <mesh name="left_link_3_col" file="collision/left_link_3.STL" />
    <mesh name="left_link_4" file="left_link_4.STL" />
    <mesh name="left_link_4_col" file="collision/left_link_4.STL" />
    <mesh name="left_link_5" file="left_link_5.STL" />
    <mesh name="left_link_5_col" file="collision/left_link_5.STL" />
    <mesh name="left_link_6" file="left_link_6.STL" />
    <mesh name="left_link_6_col" file="collision/left_link_6.STL" />
    <mesh name="left_link_7" file="left_link_7.STL" />
    <mesh name="left_link_7_col" file="collision/left_link_7.STL" />
    <mesh name="right_base_link" file="right_base_link.STL" />
    <mesh name="right_base_link_col" file="collision/right_base_link.STL" />
    <mesh name="right_link_1" file="right_link_1.STL" />
    <mesh name="right_link_1_col" file="collision/right_link_1.STL" />
    <mesh name="right_link_2" file="right_link_2.STL" />
    <mesh name="right_link_2_col" file="collision/right_link_2.STL" />
    <mesh name="right_link_3" file="right_link_3.STL" />
    <mesh name="right_link_3_col" file="collision/right_link_3.STL" />
    <mesh name="right_link_4" file="right_link_4.STL" />
    <mesh name="right_link_4_col" file="collision/right_link_4.STL" />
    <mesh name="right_link_5" file="right_link_5.STL" />
    <mesh name="right_link_5_col" file="collision/right_link_5.STL" />
    <mesh name="right_link_6" file="right_link_6.STL" />
    <mesh name="right_link_6_col" file="collision/right_link_6.STL" />
    <mesh name="right_link_7" file="right_link_7.STL" />
    <mesh name="right_link_7_col" file="collision/right_link_7.STL" />
    <mesh name="gripper_base_link" file="gripper_base_link.STL" />
    <mesh name="gripper_base_link_col" file="collision/gripper_base_link.STL" />
    <mesh name="right_finger" file="right_finger.STL" />
    <mesh name="right_finger_col" file="collision/right_finger.STL" />
    <mesh name="left_finger" file="left_finger.STL" />
    <mesh name="left_finger_col" file="collision/left_finger.STL" />
  </asset>

  <worldbody>
    <light pos="0 0 3" dir="0 0 -1" directional="true" />
    <geom name="floor" size="0 0 0.05" type="plane" material="groundplane" condim="3" contype="0" conaffinity="0" group="1" />

    <geom type="mesh" contype="0" conaffinity="0" group="1" density="0" rgba="0.792157 0.819608 0.933333 1" mesh="base_link" />
    <geom type="mesh" group="3" rgba="0.792157 0.819608 0.933333 1" mesh="base_link" />
    <site name="imu" pos="0 0 0" />
    <geom pos="-0.07 0 1.12" type="mesh" contype="0" conaffinity="0" group="1" density="0" rgba="0.79216 0.81961 0.93333 1" mesh="left_arm_attachment_point" />
    <geom pos="-0.07 0 1.12" type="mesh" group="3" rgba="0.79216 0.81961 0.93333 1" mesh="left_arm_attachment_point" />
    <geom pos="-0.07 0 1.12" quat="-2.59734e-06 -0.707108 -2.59735e-06 0.707105" type="mesh" contype="0" conaffinity="0" group="1" density="0" rgba="0.79216 0.81961 0.93333 1" mesh="left_base_link" />
    <geom pos="-0.07 0 1.12" quat="-2.59734e-06 -0.707108 -2.59735e-06 0.707105" type="mesh" group="3" rgba="0.79216 0.81961 0.93333 1" mesh="left_base_link_col" />
    <geom pos="0.07 0 1.12" type="mesh" contype="0" conaffinity="0" group="1" density="0" rgba="0.79216 0.81961 0.93333 1" mesh="right_arm_attachment_point" />
    <geom pos="0.07 0 1.12" type="mesh" group="3" rgba="0.79216 0.81961 0.93333 1" mesh="right_arm_attachment_point" />
    <geom pos="0.07 0 1.12" quat="0.707105 0 0.707108 0" type="mesh" contype="0" conaffinity="0" group="1" density="0" rgba="0.79216 0.81961 0.93333 1" mesh="right_base_link" />
    <geom pos="0.07 0 1.12" quat="0.707105 0 0.707108 0" type="mesh" group="3" rgba="0.79216 0.81961 0.93333 1" mesh="right_base_link_col" />
    <body name="left_link_1" pos="-0.2055 -9.95439e-07 1.12" quat="-2.59734e-06 -0.707108 -2.59735e-06 0.707105">
      <inertial pos="-0.00109529335918426 0.00158432100362189 -0.00494979473059115" mass="1.33500720" fullinertia="0.00101162 0.00156912 0.00091256 0.00000422 -0.00007250 0.00002970"/>
      <joint name="left_joint_0" pos="0 0 0" axis="0 0 -1" range="-2.3562 2.8798" actuatorfrcrange="-40 40" damping="0.25" frictionloss="0.35" />
      <site name="site_left_joint_0" pos="0 0 0" size="0.001" type="sphere" rgba="1 0 0 1" group="4"/>
      <geom type="mesh" contype="0" conaffinity="0" group="1" density="0" rgba="0.792157 0.819608 0.933333 1" mesh="left_link_1" />
      <geom type="mesh" group="3" rgba="0.792157 0.819608 0.933333 1" mesh="left_link_1_col" />
      <body name="left_link_2" quat="0.499998 0.5 -0.5 0.500002">
        <inertial pos="0.000508224298191348 -0.0449280282138882 -0.0206256236163859" mass="0.18252313" fullinertia="0.00061618 0.000159935 0.00050408 0.00000304 0.00000280 -0.00009588"/>
        <joint name="left_joint_1" pos="0 0 0" axis="0 0 -1" range="-3.0513 0.3491" actuatorfrcrange="-40 40" damping="0.25" frictionloss="0.35" />
      <site name="site_left_joint_1" pos="0 0 0" size="0.001" type="sphere" rgba="1 0 0 1" group="4"/>
        <geom type="mesh" contype="0" conaffinity="0" group="1" density="0" rgba="0.792157 0.819608 0.933333 1" mesh="left_link_2" />
        <geom type="mesh" group="3" rgba="0.792157 0.819608 0.933333 1" mesh="left_link_2_col" />
        <body name="left_link_3" pos="0 -0.20975 0" quat="0.499998 -0.500002 0.5 0.5">
          <inertial pos="2.83802482036803E-07 -0.000605505330037032 0.054984322701974" mass="1.04367671" fullinertia="0.00584704 0.00583635 0.00032818 -0.00000039 0.00001725 0.00000341"/>
          <joint name="left_joint_2" pos="0 0 0" axis="0 0 -1" range="-2.5307 2.5307" actuatorfrcrange="-27 27" damping="0.25" frictionloss="0.35" />
      <site name="site_left_joint_2" pos="0 0 0" size="0.001" type="sphere" rgba="1 0 0 1" group="4"/>
          <geom type="mesh" contype="0" conaffinity="0" group="1" density="0" rgba="0.792157 0.819608 0.933333 1" mesh="left_link_3" />
          <geom type="mesh" group="3" rgba="0.792157 0.819608 0.933333 1" mesh="left_link_3_col" />
          <body name="left_link_4" quat="0.707105 0.707108 0 0">
            <inertial pos="0.000110401234317883 -0.0670069142247546 0.000940172282106119" mass="0.57070680" fullinertia="0.00349959 0.00035327 0.00340757 -0.00000396 0.00000024 0.00000065"/>
            <joint name="left_joint_3" pos="0 0 0" axis="0 0 1" range="-2.0944 1.4835" actuatorfrcrange="-27 27" damping="0.25" frictionloss="0.35" />
      <site name="site_left_joint_3" pos="0 0 0" size="0.001" type="sphere" rgba="1 0 0 1" group="4"/>
            <geom type="mesh" contype="0" conaffinity="0" group="1" density="0" rgba="0.792157 0.819608 0.933333 1" mesh="left_link_4" />
            <geom type="mesh" group="3" rgba="0.792157 0.819608 0.933333 1" mesh="left_link_4_col" />
            <body name="left_link_5" pos="0 -0.24 0" quat="0.707107 -0.707107 0 0">
              <inertial pos="0.000305709664333387 0.00111778275538414 0.08453196488493" mass="0.66041024" fullinertia="0.00532998 0.00525652 0.00045790 -0.00000485 -0.00001587 -0.00005887"/>
              <joint name="left_joint_4" pos="0 0 0" axis="0 0 -1" range="-2.5307 2.5307" actuatorfrcrange="-7 7" damping="0.25" frictionloss="0.35" />
      <site name="site_left_joint_4" pos="0 0 0" size="0.001" type="sphere" rgba="1 0 0 1" group="4"/>
              <geom type="mesh" contype="0" conaffinity="0" group="1" density="0" rgba="0.792157 0.819608 0.933333 1" mesh="left_link_5" />
              <geom type="mesh" group="3" rgba="0.792157 0.819608 0.933333 1" mesh="left_link_5_col" />
              <body name="left_link_6" quat="0.707105 0.707108 0 0">
                <inertial pos="-0.00109259369146801 -0.000479735518615576 -0.000148198512131464" mass="0.41299778" fullinertia="0.00019636 0.00019157 0.00019007 -0.00000521 0.00000127 0.00000008"/>
                <joint name="left_joint_5" pos="0 0 0" axis="0 0 1" range="-0.6981 0.6981" actuatorfrcrange="-7 7" damping="0.25" frictionloss="0.35" />
      <site name="site_left_joint_5" pos="0 0 0" size="0.001" type="sphere" rgba="1 0 0 1" group="4"/>
                <geom type="mesh" contype="0" conaffinity="0" group="1" density="0" rgba="0.792157 0.819608 0.933333 1" mesh="left_link_6" />
                <geom type="mesh" group="3" rgba="0.792157 0.819608 0.933333 1" mesh="left_link_6_col" />
                <body name="left_link_7" quat="0.499998 0.5 -0.500002 -0.5">
                  <inertial pos="0.0286842428588672 6.10622663543836E-16 0.00370678756780378" mass="0.19263144" fullinertia="0.00020494 0.00048701 0.00032740 0.00000000 0.00000118 0.00000000"/>
                  <joint name="left_joint_6" pos="0 0 0" axis="0 0 -1" range="-1.5708 1.5708" actuatorfrcrange="-7 7" damping="0.25" frictionloss="0.35" />
      <site name="site_left_joint_6" pos="0 0 0" size="0.001" type="sphere" rgba="1 0 0 1" group="4"/>
                  <geom type="mesh" contype="0" conaffinity="0" group="1" density="0" rgba="0.792157 0.819608 0.933333 1" mesh="left_link_7" />
                  <geom type="mesh" group="3" rgba="0.792157 0.819608 0.933333 1" mesh="left_link_7_col" />
                  <body name="left_gripper_base_link" pos="0.06 0 0" quat="0.499998 0.5 0.500002 0.5">
                    <inertial pos="1.1802E-06 6.1128E-05 0.030778" mass="0.35269004" fullinertia="0.00042406 0.00047612 0.00018806 0.00000026 0.00000000 -0.00000006"/>
                    <geom type="mesh" contype="0" conaffinity="0" group="1" density="0" rgba="0.79216 0.81961 0.93333 1" mesh="gripper_base_link" />
                    <geom type="mesh" group="3" rgba="0.79216 0.81961 0.93333 1" mesh="gripper_base_link_col" />
                  </body>
                  <body name="left_gripper_right_finger" pos="0.139 -0.0649997 -2.90183e-07" quat="0.499998 0.5 0.500002 0.5">
                    <inertial pos="0.0034569 0.0014257 -0.003385" mass="0.04503966" fullinertia="0.00002075 0.00002763 0.00001805 -0.00000178 0.00000138 0.00000178"/>
                    <joint name="left_gripper_right_finger_joint" pos="0 0 0" axis="1 0 0" type="slide" range="0 0.045" actuatorfrcrange="-80 80" damping="0.25" frictionloss="0.35" />
      <site name="site_left_gripper_right_finger_joint" pos="0 0 0" size="0.001" type="sphere" rgba="1 0 0 1" group="4"/>
                    <geom type="mesh" contype="0" conaffinity="0" group="1" density="0" rgba="0.79216 0.81961 0.93333 1" mesh="right_finger" />
                    <geom type="mesh" group="3" rgba="0.79216 0.81961 0.93333 1" mesh="right_finger_col" />
                  </body>
                  <body name="left_gripper_left_finger" pos="0.139 0.0650003 -2.90183e-07" quat="0.499998 0.5 0.500002 0.5">
                    <inertial pos="-0.0034569 -0.0014257 -0.003385" mass="0.04503966" fullinertia="0.00002075 0.00002763 0.00001805 -0.00000178 -0.00000138 -0.00000178"/>
                    <joint name="left_gripper_left_finger_joint" pos="0 0 0" axis="-1 0 0" type="slide" range="0 0.045" actuatorfrcrange="-80 80" damping="0.25" frictionloss="0.35" />
                    <geom type="mesh" contype="0" conaffinity="0" group="1" density="0" rgba="0.79216 0.81961 0.93333 1" mesh="left_finger" />
                    <geom type="mesh" group="3" rgba="0.79216 0.81961 0.93333 1" mesh="left_finger_col" />
                  </body>
                </body>
              </body>
            </body>
          </body>
        </body>
      </body>
    </body>
    <body name="right_link_1" pos="0.2055 0 1.12" quat="-2.59734e-06 0.707108 -2.59735e-06 0.707105">
      <inertial pos="-0.0010955 -0.0015843 -0.0049495" mass="1.33502383" fullinertia="0.00145723 0.00222607 0.00135878 -0.00000490 -0.00007253 -0.00003039"/>
      <joint name="right_joint_0" pos="0 0 0" axis="0 0 -1" range="-2.8798 2.3562" actuatorfrcrange="-40 40" damping="0.25" frictionloss="0.35" />
      <site name="site_right_joint_0" pos="0 0 0" size="0.001" type="sphere" rgba="1 0 0 1" group="4"/>
      <geom quat="-3.67321e-06 0 0 1" type="mesh" contype="0" conaffinity="0" group="1" density="0" rgba="0.79216 0.81961 0.93333 1" mesh="right_link_1" />
      <geom type="mesh" group="3" rgba="0.79216 0.81961 0.93333 1" mesh="right_link_1_col" />
      <body name="right_link_2" quat="0.499998 0.5 -0.5 0.500002">
        <inertial pos="0.000508224298191348 0.0449280282138882 -0.0206256236163859" mass="0.18252313" fullinertia="0.00061618 0.000159935 0.00050408 -0.00000304 0.00000280 0.00009588"/>
        <joint name="right_joint_1" pos="0 0 0" axis="0 0 -1" range="-0.3491 3.0543" actuatorfrcrange="-40 40" damping="0.25" frictionloss="0.35" />
      <site name="site_right_joint_1" pos="0 0 0" size="0.001" type="sphere" rgba="1 0 0 1" group="4"/>
        <geom type="mesh" contype="0" conaffinity="0" group="1" density="0" rgba="0.79216 0.81961 0.93333 1" mesh="right_link_2" />
        <geom type="mesh" group="3" rgba="0.79216 0.81961 0.93333 1" mesh="right_link_2_col" />
        <body name="right_link_3" pos="0 0.20975 0" quat="0.499998 0.5 0.5 -0.500002">
          <inertial pos="3.1902E-07 0.00060542 0.054984" mass="1.04367487" fullinertia="0.00604989 0.00604509 0.00052741 0.00000106 0.00001728 -0.00000298"/>
          <joint name="right_joint_2" pos="0 0 0" axis="0 0 -1" range="-2.5307 2.5307" actuatorfrcrange="-27 27" damping="0.25" frictionloss="0.35" />
      <site name="site_right_joint_2" pos="0 0 0" size="0.001" type="sphere" rgba="1 0 0 1" group="4"/>
          <geom type="mesh" contype="0" conaffinity="0" group="1" density="0" rgba="0.79216 0.81961 0.93333 1" mesh="right_link_3" />
          <geom type="mesh" group="3" rgba="0.79216 0.81961 0.93333 1" mesh="right_link_3_col" />
          <body name="right_link_4" quat="0.707105 -0.707108 0 0">
            <inertial pos="0.000110401234317883 0.0670069142247546 0.000940172282106119" mass="0.57070674" fullinertia="0.00349959 0.00035327 0.00340757 -0.00000396 0.00000024 -0.00000066"/>
            <joint name="right_joint_3" pos="0 0 0" axis="0 0 -1" range="-2.0944 1.5708" actuatorfrcrange="-27 27" damping="0.25" frictionloss="0.35" />
      <site name="site_right_joint_3" pos="0 0 0" size="0.001" type="sphere" rgba="1 0 0 1" group="4"/>
            <geom type="mesh" contype="0" conaffinity="0" group="1" density="0" rgba="0.79216 0.81961 0.93333 1" mesh="right_link_4" />
            <geom type="mesh" group="3" rgba="0.79216 0.81961 0.93333 1" mesh="right_link_4_col" />
            <body name="right_link_5" pos="0 0.24 0" quat="0.707105 0.707108 0 0">
              <inertial pos="0.00030568 -0.0011178 0.084532" mass="0.66175571" fullinertia="0.00533902 0.00526534 0.00045833 0.00000486 -0.00001590 0.00006056"/>
              <joint name="right_joint_4" pos="0 0 0" axis="0 0 -1" range="-2.5307 2.5307" actuatorfrcrange="-7 7" damping="0.25" frictionloss="0.35" />
      <site name="site_right_joint_4" pos="0 0 0" size="0.001" type="sphere" rgba="1 0 0 1" group="4"/>
              <geom type="mesh" contype="0" conaffinity="0" group="1" density="0" rgba="0.79216 0.81961 0.93333 1" mesh="right_link_5" />
              <geom type="mesh" group="3" rgba="0.79216 0.81961 0.93333 1" mesh="right_link_5_col" />
              <body name="right_link_6" quat="-2.59734e-06 -2.59735e-06 0.707108 0.707105">
                <inertial pos="0.0010926 -0.00047974 -0.0001482" mass="0.41299783" fullinertia="0.00019636 0.00019157 0.00019007 0.00000521 -0.00000127 0.00000008"/>
                <joint name="right_joint_5" pos="0 0 0" axis="0 0 -1" range="-0.6981 0.6981" actuatorfrcrange="-7 7" damping="0.25" frictionloss="0.35" />
      <site name="site_right_joint_5" pos="0 0 0" size="0.001" type="sphere" rgba="1 0 0 1" group="4"/>
                <geom type="mesh" contype="0" conaffinity="0" group="1" density="0" rgba="0.79216 0.81961 0.93333 1" mesh="right_link_6" />
                <geom type="mesh" group="3" rgba="0.79216 0.81961 0.93333 1" mesh="right_link_6_col" />
                <body name="right_link_7" quat="-2.59734e-06 -0.707108 2.59735e-06 -0.707105">
                  <inertial pos="-5.5511E-17 0.028684 0.0037068" mass="0.19263144" fullinertia="0.00048701 0.00020494 0.00032740 0.00000000 0.00000000 0.00000118"/>
                  <joint name="right_joint_6" pos="0 0 0" axis="0 0 -1" range="-1.5708 1.5708" actuatorfrcrange="-7 7" damping="0.25" frictionloss="0.35" />
      <site name="site_right_joint_6" pos="0 0 0" size="0.001" type="sphere" rgba="1 0 0 1" group="4"/>
                  <geom type="mesh" contype="0" conaffinity="0" group="1" density="0" rgba="0.79216 0.81961 0.93333 1" mesh="right_link_7" />
                  <geom type="mesh" group="3" rgba="0.79216 0.81961 0.93333 1" mesh="right_link_7_col" />
                  <body name="right_gripper_base_link" pos="0 0.06 0" quat="-2.59734e-06 2.59735e-06 -0.707105 -0.707108">
                    <inertial pos="1.1802E-06 6.1128E-05 0.030778" mass="0.35269004" fullinertia="0.00042406 0.00047612 0.00018806 0.00000026 0.00000000 -0.00000006"/>
                    <geom type="mesh" contype="0" conaffinity="0" group="1" density="0" rgba="0.79216 0.81961 0.93333 1" mesh="gripper_base_link" />
                    <geom type="mesh" group="3" rgba="0.79216 0.81961 0.93333 1" mesh="gripper_base_link_col" />
                  </body>
                  <body name="right_gripper_right_finger" pos="0.065 0.139 7.677e-07" quat="-2.59734e-06 2.59735e-06 -0.707105 -0.707108">
                    <inertial pos="0.0034569 0.0014257 -0.003385" mass="0.04503966" fullinertia="0.00002075 0.00002763 0.00001805 -0.00000178 0.00000138 0.00000178"/>
                    <joint name="right_gripper_right_finger_joint" pos="0 0 0" axis="1 0 0" type="slide" range="0 0.045" actuatorfrcrange="-80 80" damping="0.25" frictionloss="0.35" />
      <site name="site_right_gripper_right_finger_joint" pos="0 0 0" size="0.001" type="sphere" rgba="1 0 0 1" group="4"/>
                    <geom type="mesh" contype="0" conaffinity="0" group="1" density="0" rgba="0.79216 0.81961 0.93333 1" mesh="right_finger" />
                    <geom type="mesh" group="3" rgba="0.79216 0.81961 0.93333 1" mesh="right_finger_col" />
                  </body>
                  <body name="right_gripper_left_finger" pos="-0.065 0.139 -1.87333e-07" quat="-2.59734e-06 2.59735e-06 -0.707105 -0.707108">
                    <inertial pos="-0.0034569 -0.0014257 -0.003385" mass="0.04503966" fullinertia="0.00002075 0.00002763 0.00001805 -0.00000178 -0.00000138 -0.00000178"/>
                    <joint name="right_gripper_left_finger_joint" pos="0 0 0" axis="-1 0 0" type="slide" range="0 0.045" actuatorfrcrange="-80 80" damping="0.25" frictionloss="0.35" />
                    <geom type="mesh" contype="0" conaffinity="0" group="1" density="0" rgba="0.79216 0.81961 0.93333 1" mesh="left_finger" />
                    <geom type="mesh" group="3" rgba="0.79216 0.81961 0.93333 1" mesh="left_finger_col" />
                  </body>
                </body>
              </body>
            </body>
          </body>
        </body>
      </body>
    </body>
  </worldbody>
  <equality>
    <joint joint1="left_gripper_right_finger_joint" joint2="left_gripper_left_finger_joint" polycoef="0 1 0 0 0" solimp="0.95 0.99 0.001 0.5 2" solref="0.005 1" />
    
    <joint joint1="right_gripper_right_finger_joint" joint2="right_gripper_left_finger_joint" polycoef="0 1 0 0 0" solimp="0.95 0.99 0.001 0.5 2" solref="0.005 1" />
  </equality>
  <actuator>
    <motor name="act_left_j0" joint="left_joint_0" gear="1" ctrllimited="true" ctrlrange="-40 40" />
    <motor name="act_left_j1" joint="left_joint_1" gear="1" ctrllimited="true" ctrlrange="-40 40" />
    <motor name="act_left_j2" joint="left_joint_2" gear="1" ctrllimited="true" ctrlrange="-27 27" />
    <motor name="act_left_j3" joint="left_joint_3" gear="1" ctrllimited="true" ctrlrange="-27 27" />
    <motor name="act_left_j4" joint="left_joint_4" gear="1" ctrllimited="true" ctrlrange="-7 7" />
    <motor name="act_left_j5" joint="left_joint_5" gear="1" ctrllimited="true" ctrlrange="-7 7" />
    <motor name="act_left_j6" joint="left_joint_6" gear="1" ctrllimited="true" ctrlrange="-7 7" />

    <motor name="act_left_gripper_right" joint="left_gripper_right_finger_joint" gear="1" ctrllimited="true" ctrlrange="-80 80" />
    

    <motor name="act_right_j0" joint="right_joint_0" gear="1" ctrllimited="true" ctrlrange="-40 40" />
    <motor name="act_right_j1" joint="right_joint_1" gear="1" ctrllimited="true" ctrlrange="-40 40" />
    <motor name="act_right_j2" joint="right_joint_2" gear="1" ctrllimited="true" ctrlrange="-27 27" />
    <motor name="act_right_j3" joint="right_joint_3" gear="1" ctrllimited="true" ctrlrange="-27 27" />
    <motor name="act_right_j4" joint="right_joint_4" gear="1" ctrllimited="true" ctrlrange="-7 7" />
    <motor name="act_right_j5" joint="right_joint_5" gear="1" ctrllimited="true" ctrlrange="-7 7" />
    <motor name="act_right_j6" joint="right_joint_6" gear="1" ctrllimited="true" ctrlrange="-7 7" />

    <motor name="act_right_gripper_right" joint="right_gripper_right_finger_joint" gear="1" ctrllimited="true" ctrlrange="-80 80" />
    
  </actuator>

  <sensor>
    <jointpos name="left_joint_0_pos" joint="left_joint_0" />
    <jointpos name="left_joint_1_pos" joint="left_joint_1" />
    <jointpos name="left_joint_2_pos" joint="left_joint_2" />
    <jointpos name="left_joint_3_pos" joint="left_joint_3" />
    <jointpos name="left_joint_4_pos" joint="left_joint_4" />
    <jointpos name="left_joint_5_pos" joint="left_joint_5" />
    <jointpos name="left_joint_6_pos" joint="left_joint_6" />
    <jointpos name="left_gripper_right_finger_pos" joint="left_gripper_right_finger_joint" />
    <jointpos name="left_gripper_left_finger_pos" joint="left_gripper_left_finger_joint" />

    <jointpos name="right_joint_0_pos" joint="right_joint_0" />
    <jointpos name="right_joint_1_pos" joint="right_joint_1" />
    <jointpos name="right_joint_2_pos" joint="right_joint_2" />
    <jointpos name="right_joint_3_pos" joint="right_joint_3" />
    <jointpos name="right_joint_4_pos" joint="right_joint_4" />
    <jointpos name="right_joint_5_pos" joint="right_joint_5" />
    <jointpos name="right_joint_6_pos" joint="right_joint_6" />
    <jointpos name="right_gripper_right_finger_pos" joint="right_gripper_right_finger_joint" />
    <jointpos name="right_gripper_left_finger_pos" joint="right_gripper_left_finger_joint" />

    <jointvel name="left_joint_0_vel" joint="left_joint_0" />
    <jointvel name="left_joint_1_vel" joint="left_joint_1" />
    <jointvel name="left_joint_2_vel" joint="left_joint_2" />
    <jointvel name="left_joint_3_vel" joint="left_joint_3" />
    <jointvel name="left_joint_4_vel" joint="left_joint_4" />
    <jointvel name="left_joint_5_vel" joint="left_joint_5" />
    <jointvel name="left_joint_6_vel" joint="left_joint_6" />
    <jointvel name="left_gripper_right_finger_vel" joint="left_gripper_right_finger_joint" />
    <jointvel name="left_gripper_left_finger_vel" joint="left_gripper_left_finger_joint" />

    <jointvel name="right_joint_0_vel" joint="right_joint_0" />
    <jointvel name="right_joint_1_vel" joint="right_joint_1" />
    <jointvel name="right_joint_2_vel" joint="right_joint_2" />
    <jointvel name="right_joint_3_vel" joint="right_joint_3" />
    <jointvel name="right_joint_4_vel" joint="right_joint_4" />
    <jointvel name="right_joint_5_vel" joint="right_joint_5" />
    <jointvel name="right_joint_6_vel" joint="right_joint_6" />
    <jointvel name="right_gripper_right_finger_vel" joint="right_gripper_right_finger_joint" />
    <jointvel name="right_gripper_left_finger_vel" joint="right_gripper_left_finger_joint" />

    <torque name="left_joint_0_torque" site="site_left_joint_0" />
    <torque name="left_joint_1_torque" site="site_left_joint_1" />
    <torque name="left_joint_2_torque" site="site_left_joint_2" />
    <torque name="left_joint_3_torque" site="site_left_joint_3" />
    <torque name="left_joint_4_torque" site="site_left_joint_4" />
    <torque name="left_joint_5_torque" site="site_left_joint_5" />
    <torque name="left_joint_6_torque" site="site_left_joint_6" />
    <force name="left_gripper_right_finger_torque" site="site_left_gripper_right_finger_joint" />

    <torque name="right_joint_0_torque" site="site_right_joint_0" />
    <torque name="right_joint_1_torque" site="site_right_joint_1" />
    <torque name="right_joint_2_torque" site="site_right_joint_2" />
    <torque name="right_joint_3_torque" site="site_right_joint_3" />
    <torque name="right_joint_4_torque" site="site_right_joint_4" />
    <torque name="right_joint_5_torque" site="site_right_joint_5" />
    <torque name="right_joint_6_torque" site="site_right_joint_6" />
    <force name="right_gripper_right_finger_torque" site="site_right_gripper_right_finger_joint" />

    <framequat name="imu_quat" objtype="site" objname="imu" />
    <gyro name="imu_gyro" site="imu" />
    <accelerometer name="imu_acc" site="imu" />
  </sensor>

  <contact>
    <exclude body1="right_link_1" body2="right_link_2"/>
    <exclude body1="right_link_1" body2="right_link_3"/>
    <exclude body1="right_link_2" body2="right_link_3"/>
    <exclude body1="right_link_3" body2="right_link_4"/>
    <exclude body1="right_link_4" body2="right_link_5"/>
    <exclude body1="right_link_5" body2="right_link_6"/>
    <exclude body1="right_link_5" body2="right_link_7"/>
    <exclude body1="right_link_6" body2="right_link_7"/>
    <exclude body1="left_link_1" body2="left_link_2"/>
    <exclude body1="left_link_1" body2="left_link_3"/>
    <exclude body1="left_link_2" body2="left_link_3"/>
    <exclude body1="left_link_3" body2="left_link_4"/>
    <exclude body1="left_link_4" body2="left_link_5"/>
    <exclude body1="left_link_5" body2="left_link_6"/>
    <exclude body1="left_link_5" body2="left_link_7"/>
    <exclude body1="left_link_6" body2="left_link_7"/>
    <exclude body1="left_link_7" body2="left_gripper_right_finger"/>
    <exclude body1="left_link_7" body2="left_gripper_left_finger"/>
    <exclude body1="right_link_7" body2="right_gripper_right_finger"/>
    <exclude body1="right_link_7" body2="right_gripper_left_finger"/>

  </contact>

  <keyframe>
    <key name="home" qpos="0 0 0 0 0 0 0 0 0 0 0 0 0 0 0 0 0 0" />
  </keyframe>

</mujoco>