<?xml version="1.0" ?>
<!-- =================================================================================== -->
<!-- |    This document was autogenerated by xacro from /home/ubuntu/ros2_ws/src/description/dual_arm_support/urdf/dual_arm_robot.urdf.xacro | -->
<!-- |    EDITING THIS FILE BY HAND IS NOT RECOMMENDED                                 | -->
<!-- =================================================================================== -->
<robot name="dual_arm_robot">
  <link name="base_footprint"/>
  <joint name="support_base_joint" type="fixed">
    <origin rpy="0 0 0" xyz="0 0 0"/>
    <parent link="base_footprint"/>
    <child link="base_link"/>
  </joint>
  <link name="base_link">
    <inertial>
      <origin rpy="0 0 0" xyz="4.4390908945955E-08 6.15097131842071E-08 0.625"/>
      <mass value="2.19423393695423"/>
      <inertia ixx="0.287192437664211" ixy="2.69040881704817E-09" ixz="9.91925905799376E-16" iyy="0.287192448392283" iyz="5.97292812641121E-20" izz="0.00296979830799831"/>
    </inertial>
    <visual>
      <origin rpy="0 0 0" xyz="0 0 0"/>
      <geometry>
        <mesh filename="package://dual_arm_support/meshes/base_link.STL"/>
      </geometry>
      <material name="">
        <color rgba="0.792156862745098 0.819607843137255 0.933333333333333 1"/>
      </material>
    </visual>
    <collision>
      <origin rpy="0 0 0" xyz="0 0 0"/>
      <geometry>
        <mesh filename="package://dual_arm_support/meshes/base_link.STL"/>
      </geometry>
    </collision>
  </link>
  <link name="left_arm_attachment_point">
    <inertial>
      <origin rpy="0 0 0" xyz="0.015 -4.7603E-17 0"/>
      <mass value="0.1018"/>
      <inertia ixx="5.7895E-05" ixy="-7.5643E-20" ixz="7.4422E-20" iyy="3.6583E-05" iyz="4.1359E-21" izz="3.6583E-05"/>
    </inertial>
    <visual>
      <origin rpy="0 0 0" xyz="0 0 0"/>
      <geometry>
        <mesh filename="package://dual_arm_support/meshes/left_arm_attachment_point.STL"/>
      </geometry>
      <material name="">
        <color rgba="0.79216 0.81961 0.93333 1"/>
      </material>
    </visual>
    <collision>
      <origin rpy="0 0 0" xyz="0 0 0"/>
      <geometry>
        <mesh filename="package://dual_arm_support/meshes/left_arm_attachment_point.STL"/>
      </geometry>
    </collision>
  </link>
  <joint name="left_arm_attachment_joint" type="fixed">
    <origin rpy="0 0 0" xyz="-0.07 0 1.12"/>
    <parent link="base_link"/>
    <child link="left_arm_attachment_point"/>
    <axis xyz="0 0 0"/>
  </joint>
  <link name="right_arm_attachment_point">
    <inertial>
      <origin rpy="0 0 0" xyz="-0.015 5.7142E-17 0"/>
      <mass value="0.1018"/>
      <inertia ixx="5.7895E-05" ixy="-7.5643E-20" ixz="7.4422E-20" iyy="3.6583E-05" iyz="3.3087E-21" izz="3.6583E-05"/>
    </inertial>
    <visual>
      <origin rpy="0 0 0" xyz="0 0 0"/>
      <geometry>
        <mesh filename="package://dual_arm_support/meshes/right_arm_attachment_point.STL"/>
      </geometry>
      <material name="">
        <color rgba="0.79216 0.81961 0.93333 1"/>
      </material>
    </visual>
    <collision>
      <origin rpy="0 0 0" xyz="0 0 0"/>
      <geometry>
        <mesh filename="package://dual_arm_support/meshes/right_arm_attachment_point.STL"/>
      </geometry>
    </collision>
  </link>
  <joint name="right_arm_attachment_joint" type="fixed">
    <origin rpy="0 0 0" xyz="0.07 0 1.12"/>
    <parent link="base_link"/>
    <child link="right_arm_attachment_point"/>
    <axis xyz="0 0 0"/>
  </joint>
  <joint name="left_arm_base_joint" type="fixed">
    <origin rpy="0 1.5708 3.1416" xyz="0 0 0"/>
    <parent link="left_arm_attachment_point"/>
    <child link="left_base_link"/>
  </joint>
  <link name="left_base_link">
    <inertial>
      <origin
        xyz="0.00017935 0.0018838 0.038665"
        rpy="0 0 0" />
      <mass
        value="1.22564" />
      <inertia
        ixx="0.00256728"
        ixy="0.00000020"
        ixz="-0.00002190"
        iyy="0.00265135"
        iyz="-0.00003114"
        izz="0.00082058" />
    </inertial>
    <visual>
      <origin rpy="0 0 0" xyz="0 0 0"/>
      <geometry>
        <mesh filename="package://left_arm_description/meshes/left_base_link.STL"/>
      </geometry>
      <material name="">
        <color rgba="0.79216 0.81961 0.93333 1"/>
      </material>
    </visual>
    <collision>
      <origin rpy="0 0 0" xyz="0 0 0"/>
      <geometry>
        <mesh filename="package://left_arm_description/meshes/left_base_link.STL"/>
      </geometry>
    </collision>
  </link>
  <link name="left_link_1">
    <inertial>
      <origin rpy="0 0 0" xyz="-0.00109529335918426 0.00158432100362189 -0.00494979473059115"/>
      <mass value="1.33500720"/>
      <inertia ixx="0.00101162" ixy="0.00000422" ixz="-0.00007250" iyy="0.00156912" iyz="0.00002970" izz="0.00091256"/>
    </inertial>
    <visual>
      <origin rpy="0 0 0" xyz="0 0 0"/>
      <geometry>
        <mesh filename="package://left_arm_description/meshes/left_link_1.STL"/>
      </geometry>
      <material name="">
        <color rgba="0.792156862745098 0.819607843137255 0.933333333333333 1"/>
      </material>
    </visual>
    <collision>
      <origin rpy="0 0 0" xyz="0 0 0"/>
      <geometry>
        <mesh filename="package://left_arm_description/meshes/left_link_1.STL"/>
      </geometry>
    </collision>
  </link>
  <joint name="left_joint_0" type="revolute">
    <origin rpy="0 0 0" xyz="0 0 0.1355"/>
    <parent link="left_base_link"/>
    <child link="left_link_1"/>
    <axis xyz="0 0 -1"/>
    <limit effort="40" lower="-2.3562" upper="2.8798" velocity="10.472"/>
    <dynamics damping="0.1" friction="0.1"/>
  </joint>
  <link name="left_link_2">
    <inertial>
      <origin rpy="0 0 0" xyz="0.000508224298191348 -0.0449280282138882 -0.0206256236163859"/>
      <mass value="0.18252313"/>
      <inertia ixx="0.00061618" ixy="0.00000304" ixz="0.00000280" iyy="0.000159935" iyz="-0.00009588" izz="0.00050408"/>
    </inertial>
    <visual>
      <origin rpy="0 0 0" xyz="0 0 0"/>
      <geometry>
        <mesh filename="package://left_arm_description/meshes/left_link_2.STL"/>
      </geometry>
      <material name="">
        <color rgba="0.792156862745098 0.819607843137255 0.933333333333333 1"/>
      </material>
    </visual>
    <collision>
      <origin rpy="0 0 0" xyz="0 0 0"/>
      <geometry>
        <mesh filename="package://left_arm_description/meshes/left_link_2.STL"/>
      </geometry>
    </collision>
  </link>
  <joint name="left_joint_1" type="revolute">
    <origin rpy="1.5708 -1.5708 0" xyz="0 0 0"/>
    <parent link="left_link_1"/>
    <child link="left_link_2"/>
    <axis xyz="0 0 -1"/>
    <limit effort="40" lower="-3.0513" upper="0.3491" velocity="10.472"/>
    <dynamics damping="0.1" friction="0.1"/>
  </joint>
  <link name="left_link_3">
    <inertial>
      <origin rpy="0 0 0" xyz="2.83802482036803E-07 -0.000605505330037032 0.054984322701974"/>
      <mass value="1.04367671"/>
      <inertia ixx="0.00584704" ixy="-0.00000039" ixz="0.00001725" iyy="0.00583635" iyz="0.00000341" izz="0.00032818"/>
    </inertial>
    <visual>
      <origin rpy="0 0 0" xyz="0 0 0"/>
      <geometry>
        <mesh filename="package://left_arm_description/meshes/left_link_3.STL"/>
      </geometry>
      <material name="">
        <color rgba="0.792156862745098 0.819607843137255 0.933333333333333 1"/>
      </material>
    </visual>
    <collision>
      <origin rpy="0 0 0" xyz="0 0 0"/>
      <geometry>
        <mesh filename="package://left_arm_description/meshes/left_link_3.STL"/>
      </geometry>
    </collision>
  </link>
  <joint name="left_joint_2" type="revolute">
    <origin rpy="0 1.5708 1.5708" xyz="0 -0.20975 0"/>
    <parent link="left_link_2"/>
    <child link="left_link_3"/>
    <axis xyz="0 0 -1"/>
    <limit effort="27" lower="-2.5307" upper="2.5307" velocity="3.77"/>
    <dynamics damping="0.1" friction="0.1"/>
  </joint>
  <link name="left_link_4">
    <inertial>
      <origin rpy="0 0 0" xyz="0.000110401234317883 -0.0670069142247546 0.000940172282106119"/>
      <mass value="0.57070680"/>
      <inertia ixx="0.00349959" ixy="0.00000396" ixz="0.00000024" iyy="0.00035327" iyz="0.00000065" izz="0.00340757"/>

    </inertial>
    <visual>
      <origin rpy="0 0 0" xyz="0 0 0"/>
      <geometry>
        <mesh filename="package://left_arm_description/meshes/left_link_4.STL"/>
      </geometry>
      <material name="">
        <color rgba="0.792156862745098 0.819607843137255 0.933333333333333 1"/>
      </material>
    </visual>
    <collision>
      <origin rpy="0 0 0" xyz="0 0 0"/>
      <geometry>
        <mesh filename="package://left_arm_description/meshes/left_link_4.STL"/>
      </geometry>
    </collision>
  </link>
  <joint name="left_joint_3" type="revolute">
    <origin rpy="1.5708 0 0" xyz="0 0 0"/>
    <parent link="left_link_3"/>
    <child link="left_link_4"/>
    <axis xyz="0 0 1"/>
    <limit effort="27" lower="-2.0944" upper="1.4835" velocity="3.77"/>
    <dynamics damping="0.1" friction="0.1"/>
  </joint>
  <link name="left_link_5">
    <inertial>
      <origin rpy="0 0 0" xyz="0.000305709664333387 0.00111778275538414 0.08453196488493"/>
      <mass value="0.66041024"/>
      <inertia ixx="0.00532998" ixy="-0.00000485" ixz="-0.00001587" iyy="0.00525652" iyz="-0.00005887" izz="0.00045790"/>

    </inertial>
    <visual>
      <origin rpy="0 0 0" xyz="0 0 0"/>
      <geometry>
        <mesh filename="package://left_arm_description/meshes/left_link_5.STL"/>
      </geometry>
      <material name="">
        <color rgba="0.792156862745098 0.819607843137255 0.933333333333333 1"/>
      </material>
    </visual>
    <collision>
      <origin rpy="0 0 0" xyz="0 0 0"/>
      <geometry>
        <mesh filename="package://left_arm_description/meshes/left_link_5.STL"/>
      </geometry>
    </collision>
  </link>
  <joint name="left_joint_4" type="revolute">
    <origin rpy="-1.5707963267949 0 0" xyz="0 -0.24 0"/>
    <parent link="left_link_4"/>
    <child link="left_link_5"/>
    <axis xyz="0 0 -1"/>
    <limit effort="7.0" lower="-2.5307" upper="2.5307" velocity="12.566"/>
    <dynamics damping="0.1" friction="0.1"/>
  </joint>
  <link name="left_link_6">
    <inertial>
      <origin rpy="0 0 0" xyz="-0.00109259369146801 -0.000479735518615576 -0.000148198512131464"/>
      <mass value="0.41299778"/>
      <inertia ixx="0.00019636" ixy="-0.00000521" ixz="0.00000127" iyy="0.00019157" iyz="0.00000008" izz="0.00019007"/>

    </inertial>
    <visual>
      <origin rpy="0 0 0" xyz="0 0 0"/>
      <geometry>
        <mesh filename="package://left_arm_description/meshes/left_link_6.STL"/>
      </geometry>
      <material name="">
        <color rgba="0.792156862745098 0.819607843137255 0.933333333333333 1"/>
      </material>
    </visual>
    <collision>
      <origin rpy="0 0 0" xyz="0 0 0"/>
      <geometry>
        <mesh filename="package://left_arm_description/meshes/left_link_6.STL"/>
      </geometry>
    </collision>
  </link>
  <joint name="left_joint_5" type="revolute">
    <origin rpy="1.5708 0 0" xyz="0 0 0"/>
    <parent link="left_link_5"/>
    <child link="left_link_6"/>
    <axis xyz="0 0 1"/>
    <limit effort="7.0" lower="-0.6981" upper="0.6981" velocity="12.566"/>
    <dynamics damping="0.1" friction="0.1"/>
  </joint>
  <link name="left_link_7">
    <inertial>
      <origin rpy="0 0 0" xyz="0.0286842428588672 6.10622663543836E-16 0.00370678756780378"/>
      <mass value="0.19263144"/>
      <inertia ixx="0.00020494" ixy="0.00000000" ixz="0.00000118" iyy="0.00048701" iyz="0.00000000" izz="0.00032740"/>

    </inertial>
    <visual>
      <origin rpy="0 0 0" xyz="0 0 0"/>
      <geometry>
        <mesh filename="package://left_arm_description/meshes/left_link_7.STL"/>
      </geometry>
      <material name="">
        <color rgba="0.792156862745098 0.819607843137255 0.933333333333333 1"/>
      </material>
    </visual>
    <collision>
      <origin rpy="0 0 0" xyz="0 0 0"/>
      <geometry>
        <mesh filename="package://left_arm_description/meshes/left_link_7.STL"/>
      </geometry>
    </collision>
  </link>
  <joint name="left_joint_6" type="revolute">
    <origin rpy="1.5708 0 -1.5708" xyz="0 0 0"/>
    <parent link="left_link_6"/>
    <child link="left_link_7"/>
    <axis xyz="0 0 -1"/>
    <limit effort="7.0" lower="-1.5708" upper="1.5708" velocity="12.566"/>
    <dynamics damping="0.1" friction="0.1"/>
  </joint>
  <link name="left_attachment_point"/>
  <joint name="left_attachment_fixed_joint" type="fixed">
    <origin rpy="1.5708 0 1.5708" xyz="0.06 0 0"/>
    <parent link="left_link_7"/>
    <child link="left_attachment_point"/>
  </joint>
  <joint name="right_arm_base_joint" type="fixed">
    <origin rpy="0 1.5708 0" xyz="0 0 0"/>
    <parent link="right_arm_attachment_point"/>
    <child link="right_base_link"/>
  </joint>
  <link name="right_base_link">
    <inertial>
      <origin rpy="0 0 0" xyz="0.00017935 -0.0018838 0.038665"/>
      <mass value="1.22564018"/>
      <inertia ixx="0.00301289" ixy="-0.00000023" ixz="-0.00002258" iyy="0.00309754" iyz="0.00003044" izz="0.00147750"/>
    </inertial>
    <visual>
      <origin rpy="0 0 0" xyz="0 0 0"/>
      <geometry>
        <mesh filename="package://right_arm_description/meshes/right_base_link.STL"/>
      </geometry>
      <material name="">
        <color rgba="0.79216 0.81961 0.93333 1"/>
      </material>
    </visual>
    <collision>
      <origin rpy="0 0 0" xyz="0 0 0"/>
      <geometry>
        <mesh filename="package://right_arm_description/meshes/right_base_link.STL"/>
      </geometry>
    </collision>
  </link>
  <link name="right_link_1">
    <inertial>
      <origin rpy="0 0 0" xyz="-0.0010955 -0.0015843 -0.0049495"/>
      <mass value="1.33502383"/>
      <inertia ixx="0.00145723" ixy="-0.00000490" ixz="-0.00007253" iyy="0.00222607" iyz="-0.00003039" izz="0.00135878"/>
    </inertial>
    <visual>
      <origin rpy="0 0 3.1416" xyz="0 0 0"/>
      <geometry>
        <mesh filename="package://right_arm_description/meshes/right_link_1.STL"/>
      </geometry>
      <material name="">
        <color rgba="0.79216 0.81961 0.93333 1"/>
      </material>
    </visual>
    <collision>
      <origin rpy="0 0 0" xyz="0 0 0"/>
      <geometry>
        <mesh filename="package://right_arm_description/meshes/right_link_1.STL"/>
      </geometry>
    </collision>
  </link>
  <joint name="right_joint_0" type="revolute">
    <origin rpy="0 0 3.1416" xyz="0 0 0.1355"/>
    <parent link="right_base_link"/>
    <child link="right_link_1"/>
    <axis xyz="0 0 -1"/>
    <limit effort="40" lower="-2.8798" upper="2.3562" velocity="10.472"/>
    <dynamics damping="0.1" friction="0.1"/>
  </joint>
  <link name="right_link_2">
    <inertial>
      <origin rpy="0 0 0" xyz="0.00050822 0.044928 -0.020626"/>
      <mass value="0.18252313"/>
      <inertia ixx="0.00061618" ixy="-0.00000304" ixz="0.00000280" iyy="0.00015993" iyz="0.00009588" izz="0.00050408"/>
    </inertial>
    <visual>
      <origin rpy="0 0 0" xyz="0 0 0"/>
      <geometry>
        <mesh filename="package://right_arm_description/meshes/right_link_2.STL"/>
      </geometry>
      <material name="">
        <color rgba="0.79216 0.81961 0.93333 1"/>
      </material>
    </visual>
    <collision>
      <origin rpy="0 0 0" xyz="0 0 0"/>
      <geometry>
        <mesh filename="package://right_arm_description/meshes/right_link_2.STL"/>
      </geometry>
    </collision>
  </link>
  <joint name="right_joint_1" type="revolute">
    <origin rpy="1.5708 -1.5708 0" xyz="0 0 0"/>
    <parent link="right_link_1"/>
    <child link="right_link_2"/>
    <axis xyz="0 0 -1"/>
    <limit effort="40" lower="-0.3491" upper="3.0543" velocity="10.472"/>
    <dynamics damping="0.1" friction="0.1"/>
  </joint>
  <link name="right_link_3">
    <inertial>
      <origin rpy="0 0 0" xyz="3.1902E-07 0.00060542 0.054984"/>
      <mass value="1.04367487"/>
      <inertia ixx="0.00604989" ixy="0.00000106" ixz="0.00001728" iyy="0.00604509" iyz="-0.00000298" izz="0.00052741"/>
    </inertial>
    <visual>
      <origin rpy="0 0 0" xyz="0 0 0"/>
      <geometry>
        <mesh filename="package://right_arm_description/meshes/right_link_3.STL"/>
      </geometry>
      <material name="">
        <color rgba="0.79216 0.81961 0.93333 1"/>
      </material>
    </visual>
    <collision>
      <origin rpy="0 0 0" xyz="0 0 0"/>
      <geometry>
        <mesh filename="package://right_arm_description/meshes/right_link_3.STL"/>
      </geometry>
    </collision>
  </link>
  <joint name="right_joint_2" type="revolute">
    <origin rpy="1.5708 1.5708 0" xyz="0 0.20975 0"/>
    <parent link="right_link_2"/>
    <child link="right_link_3"/>
    <axis xyz="0 0 -1"/>
    <limit effort="27" lower="-2.5307" upper="2.5307" velocity="3.7699"/>
    <dynamics damping="0.1" friction="0.1"/>
  </joint>
  <link name="right_link_4">
    <inertial>
      <origin rpy="0 0 0" xyz="0.0001104 0.067007 0.00094041"/>
      <mass value="0.57070674"/>
      <inertia ixx="0.00349959" ixy="-0.00000396" ixz="0.00000024" iyy="0.00035327" iyz="-0.00000066" izz="0.00340757"/>
    </inertial>
    <visual>
      <origin rpy="0 0 0" xyz="0 0 0"/>
      <geometry>
        <mesh filename="package://right_arm_description/meshes/right_link_4.STL"/>
      </geometry>
      <material name="">
        <color rgba="0.79216 0.81961 0.93333 1"/>
      </material>
    </visual>
    <collision>
      <origin rpy="0 0 0" xyz="0 0 0"/>
      <geometry>
        <mesh filename="package://right_arm_description/meshes/right_link_4.STL"/>
      </geometry>
    </collision>
  </link>
  <joint name="right_joint_3" type="revolute">
    <origin rpy="-1.5708 0 0" xyz="0 0 0"/>
    <parent link="right_link_3"/>
    <child link="right_link_4"/>
    <axis xyz="0 0 -1"/>
    <limit effort="27" lower="-2.0944" upper="1.5708" velocity="3.7699"/>
    <dynamics damping="0.1" friction="0.1"/>
  </joint>
  <link name="right_link_5">
    <inertial>
      <origin rpy="0 0 0" xyz="0.00030568 -0.0011178 0.084532"/>
      <mass value="0.66175571"/>
      <inertia ixx="0.00533902" ixy="0.00000486" ixz="-0.00001590" iyy="0.00526534" iyz="0.00006056" izz="0.00045833"/>
    </inertial>
    <visual>
      <origin rpy="0 0 0" xyz="0 0 0"/>
      <geometry>
        <mesh filename="package://right_arm_description/meshes/right_link_5.STL"/>
      </geometry>
      <material name="">
        <color rgba="0.79216 0.81961 0.93333 1"/>
      </material>
    </visual>
    <collision>
      <origin rpy="0 0 0" xyz="0 0 0"/>
      <geometry>
        <mesh filename="package://right_arm_description/meshes/right_link_5.STL"/>
      </geometry>
    </collision>
  </link>
  <joint name="right_joint_4" type="revolute">
    <origin rpy="1.5708 0 0" xyz="0 0.24 0"/>
    <parent link="right_link_4"/>
    <child link="right_link_5"/>
    <axis xyz="0 0 -1"/>
    <limit effort="7" lower="-2.5307" upper="2.5307" velocity="12.566"/>
    <dynamics damping="0.1" friction="0.1"/>
  </joint>
  <link name="right_link_6">
    <inertial>
      <origin rpy="0 0 0" xyz="0.0010926 -0.00047974 -0.0001482"/>
      <mass value="0.41299783"/>
      <inertia ixx="0.00019636" ixy="0.00000521" ixz="-0.00000127" iyy="0.00019157" iyz="0.00000008" izz="0.00019007"/>
    </inertial>
    <visual>
      <origin rpy="0 0 0" xyz="0 0 0"/>
      <geometry>
        <mesh filename="package://right_arm_description/meshes/right_link_6.STL"/>
      </geometry>
      <material name="">
        <color rgba="0.79216 0.81961 0.93333 1"/>
      </material>
    </visual>
    <collision>
      <origin rpy="0 0 0" xyz="0 0 0"/>
      <geometry>
        <mesh filename="package://right_arm_description/meshes/right_link_6.STL"/>
      </geometry>
    </collision>
  </link>
  <joint name="right_joint_5" type="revolute">
    <origin rpy="1.5708 0 3.1416" xyz="0 0 0"/>
    <parent link="right_link_5"/>
    <child link="right_link_6"/>
    <axis xyz="0 0 -1"/>
    <limit effort="7" lower="-0.6981" upper="0.6981" velocity="12.566"/>
    <dynamics damping="0.1" friction="0.1"/>
  </joint>
  <link name="right_link_7">
    <inertial>
      <origin rpy="0 0 0" xyz="-5.5511E-17 0.028684 0.0037068"/>
      <mass value="0.19263144"/>
      <inertia ixx="0.00048701" ixy="0.00000000" ixz="0.00000000" iyy="0.00020494" iyz="0.00000118" izz="0.00032740"/>
    </inertial>
    <visual>
      <origin rpy="0 0 0" xyz="0 0 0"/>
      <geometry>
        <mesh filename="package://right_arm_description/meshes/right_link_7.STL"/>
      </geometry>
      <material name="">
        <color rgba="0.79216 0.81961 0.93333 1"/>
      </material>
    </visual>
    <collision>
      <origin rpy="0 0 0" xyz="0 0 0"/>
      <geometry>
        <mesh filename="package://right_arm_description/meshes/right_link_7.STL"/>
      </geometry>
    </collision>
  </link>
  <joint name="right_joint_6" type="revolute">
    <origin rpy="0 -1.5708 -3.1416" xyz="0 0 0"/>
    <parent link="right_link_6"/>
    <child link="right_link_7"/>
    <axis xyz="0 0 -1"/>
    <limit effort="7" lower="-1.5708" upper="1.5708" velocity="12.566"/>
    <dynamics damping="0.1" friction="0.1"/>
  </joint>
  <link name="right_attachment_point"/>
  <joint name="right_attachment_fixed_joint" type="fixed">
    <origin rpy="-1.5708 -3.1416 0" xyz="0 0.06 0"/>
    <parent link="right_link_7"/>
    <child link="right_attachment_point"/>
  </joint>
  <joint name="left_gripper_gripper_base_joint" type="fixed">
    <origin rpy="0 0 0" xyz="0 0 0"/>
    <parent link="left_attachment_point"/>
    <child link="left_gripper_gripper_base_link"/>
  </joint>
  <link name="left_gripper_gripper_base_link">
    <inertial>
      <origin rpy="0 0 0" xyz="1.1802E-06 6.1128E-05 0.030778"/>
      <mass value="0.35269004"/>
      <inertia ixx="0.00042406" ixy="0.00000026" ixz="0.00000000" iyy="0.00047612" iyz="-0.00000006" izz="0.00018806"/>
    </inertial>
    <visual>
      <origin rpy="0 0 0" xyz="0 0 0"/>
      <geometry>
        <mesh filename="package://gripper_description/meshes/gripper_base_link.STL"/>
      </geometry>
      <material name="">
        <color rgba="0.79216 0.81961 0.93333 1"/>
      </material>
    </visual>
    <collision>
      <origin rpy="0 0 0" xyz="0 0 0"/>
      <geometry>
        <mesh filename="package://gripper_description/meshes/gripper_base_link.STL"/>
      </geometry>
    </collision>
  </link>
  <link name="left_gripper_right_finger">
    <inertial>
      <origin rpy="0 0 0" xyz="0.0034569 0.0014257 -0.003385"/>
      <mass value="0.04503966"/>
      <inertia ixx="0.00002075" ixy="-0.00000178" ixz="0.00000138" iyy="0.00002763" iyz="0.00000178" izz="0.00001805"/>
    </inertial>
    <visual>
      <origin rpy="0 0 0" xyz="0 0 0"/>
      <geometry>
        <mesh filename="package://gripper_description/meshes/right_finger.STL"/>
      </geometry>
      <material name="">
        <color rgba="0.79216 0.81961 0.93333 1"/>
      </material>
    </visual>
    <collision>
      <origin rpy="0 0 0" xyz="0 0 0"/>
      <geometry>
        <mesh filename="package://gripper_description/meshes/right_finger.STL"/>
      </geometry>
    </collision>
  </link>
  <joint name="left_gripper_right_finger_joint" type="prismatic">
    <origin rpy="0 0 0" xyz="-0.065 0 0.079"/>
    <parent link="left_gripper_gripper_base_link"/>
    <child link="left_gripper_right_finger"/>
    <axis xyz="1 0 0"/>
    <limit effort="80" lower="0" upper="0.045" velocity="0.125"/>
    <dynamics damping="0.1" friction="0.1"/>
  </joint>
  <link name="left_gripper_left_finger">
    <inertial>
      <origin rpy="0 0 0" xyz="-0.0034569 -0.0014257 -0.003385"/>
      <mass value="0.04503966"/>
      <inertia ixx="0.00002075" ixy="-0.00000178" ixz="-0.00000138" iyy="0.00002763" iyz="-0.00000178" izz="0.00001805"/>
    </inertial>
    <visual>
      <origin rpy="0 0 0" xyz="0 0 0"/>
      <geometry>
        <mesh filename="package://gripper_description/meshes/left_finger.STL"/>
      </geometry>
      <material name="">
        <color rgba="0.79216 0.81961 0.93333 1"/>
      </material>
    </visual>
    <collision>
      <origin rpy="0 0 0" xyz="0 0 0"/>
      <geometry>
        <mesh filename="package://gripper_description/meshes/left_finger.STL"/>
      </geometry>
    </collision>
  </link>
  <joint name="left_gripper_left_finger_joint" type="prismatic">
    <origin rpy="0 0 0" xyz="0.065 0 0.079"/>
    <parent link="left_gripper_gripper_base_link"/>
    <child link="left_gripper_left_finger"/>
    <axis xyz="-1 0 0"/>
    <limit effort="80" lower="0" upper="0.045" velocity="0.125"/>
    <dynamics damping="0.1" friction="0.1"/>
    <mimic joint="left_gripper_right_finger_joint" multiplier="1" offset="0"/>
  </joint>
  <joint name="right_gripper_gripper_base_joint" type="fixed">
    <origin rpy="0 0 0" xyz="0 0 0"/>
    <parent link="right_attachment_point"/>
    <child link="right_gripper_gripper_base_link"/>
  </joint>
  <link name="right_gripper_gripper_base_link">
    <inertial>
      <origin
        xyz="1.1802E-06 6.1128E-05 0.030778"
        rpy="0 0 0" />
      <mass
        value="0.35269004" />
      <inertia
        ixx="0.00042406"
        ixy="0.00000026"
        ixz="0.00000000"
        iyy="0.00047612"
        iyz="-0.00000006"
        izz="0.00018806" />
    </inertial>
    <visual>
      <origin rpy="0 0 0" xyz="0 0 0"/>
      <geometry>
        <mesh filename="package://gripper_description/meshes/gripper_base_link.STL"/>
      </geometry>
      <material name="">
        <color rgba="0.79216 0.81961 0.93333 1"/>
      </material>
    </visual>
    <collision>
      <origin rpy="0 0 0" xyz="0 0 0"/>
      <geometry>
        <mesh filename="package://gripper_description/meshes/gripper_base_link.STL"/>
      </geometry>
    </collision>
  </link>
  <link name="right_gripper_right_finger">
    <inertial>
      <origin rpy="0 0 0" xyz="0.0034569 0.0014257 -0.003385"/>
      <mass value="0.04503966"/>
      <inertia ixx="0.00002075" ixy="-0.00000178" ixz="0.00000138" iyy="0.00002763" iyz="0.00000178" izz="0.00001805"/>
    </inertial>
    <visual>
      <origin rpy="0 0 0" xyz="0 0 0"/>
      <geometry>
        <mesh filename="package://gripper_description/meshes/right_finger.STL"/>
      </geometry>
      <material name="">
        <color rgba="0.79216 0.81961 0.93333 1"/>
      </material>
    </visual>
    <collision>
      <origin rpy="0 0 0" xyz="0 0 0"/>
      <geometry>
        <mesh filename="package://gripper_description/meshes/right_finger.STL"/>
      </geometry>
    </collision>
  </link>
  <joint name="right_gripper_right_finger_joint" type="prismatic">
    <origin rpy="0 0 0" xyz="-0.065 0 0.079"/>
    <parent link="right_gripper_gripper_base_link"/>
    <child link="right_gripper_right_finger"/>
    <axis xyz="1 0 0"/>
    <limit effort="80" lower="0" upper="0.045" velocity="0.125"/>
    <dynamics damping="0.1" friction="0.1"/>
  </joint>
  <link name="right_gripper_left_finger">
    <inertial>
      <origin rpy="0 0 0" xyz="-0.0034569 -0.0014257 -0.003385"/>
      <mass value="0.04503966" />
      <inertia ixx="0.00002075" ixy="-0.00000178" ixz="-0.00000138" iyy="0.00002763" iyz="-0.00000178" izz="0.00001805" />
    </inertial>
    <visual>
      <origin rpy="0 0 0" xyz="0 0 0"/>
      <geometry>
        <mesh filename="package://gripper_description/meshes/left_finger.STL"/>
      </geometry>
      <material name="">
        <color rgba="0.79216 0.81961 0.93333 1"/>
      </material>
    </visual>
    <collision>
      <origin rpy="0 0 0" xyz="0 0 0"/>
      <geometry>
        <mesh filename="package://gripper_description/meshes/left_finger.STL"/>
      </geometry>
    </collision>
  </link>
  <joint name="right_gripper_left_finger_joint" type="prismatic">
    <origin rpy="0 0 0" xyz="0.065 0 0.079"/>
    <parent link="right_gripper_gripper_base_link"/>
    <child link="right_gripper_left_finger"/>
    <axis xyz="-1 0 0"/>
    <limit effort="80" lower="0" upper="0.045" velocity="0.125"/>
    <dynamics damping="0.1" friction="0.1"/>
    <mimic joint="right_gripper_right_finger_joint" multiplier="1" offset="0"/>
  </joint>
  <ros2_control name="MujocoSystem" type="system">
    <hardware>
      <plugin>eiriarm_mujoco/MujocoHardware</plugin>
      <param name="model_path">/home/ubuntu/ros2_ws/install/dual_arm_support/share/dual_arm_support/mjcf/dual_arm_robot.xml</param>
    </hardware>
    <joint name="left_joint_0">
      <command_interface name="effort"/>
      <state_interface name="position"/>
      <state_interface name="velocity"/>
      <state_interface name="effort"/>
    </joint>
    <joint name="left_joint_1">
      <command_interface name="effort"/>
      <state_interface name="position"/>
      <state_interface name="velocity"/>
      <state_interface name="effort"/>
    </joint>
    <joint name="left_joint_2">
      <command_interface name="effort"/>
      <state_interface name="position"/>
      <state_interface name="velocity"/>
      <state_interface name="effort"/>
    </joint>
    <joint name="left_joint_3">
      <command_interface name="effort"/>
      <state_interface name="position"/>
      <state_interface name="velocity"/>
      <state_interface name="effort"/>
    </joint>
    <joint name="left_joint_4">
      <command_interface name="effort"/>
      <state_interface name="position"/>
      <state_interface name="velocity"/>
      <state_interface name="effort"/>
    </joint>
    <joint name="left_joint_5">
      <command_interface name="effort"/>
      <state_interface name="position"/>
      <state_interface name="velocity"/>
      <state_interface name="effort"/>
    </joint>
    <joint name="left_joint_6">
      <command_interface name="effort"/>
      <state_interface name="position"/>
      <state_interface name="velocity"/>
      <state_interface name="effort"/>
    </joint>
    <joint name="right_joint_0">
      <command_interface name="effort"/>
      <state_interface name="position"/>
      <state_interface name="velocity"/>
      <state_interface name="effort"/>
    </joint>
    <joint name="right_joint_1">
      <command_interface name="effort"/>
      <state_interface name="position"/>
      <state_interface name="velocity"/>
      <state_interface name="effort"/>
    </joint>
    <joint name="right_joint_2">
      <command_interface name="effort"/>
      <state_interface name="position"/>
      <state_interface name="velocity"/>
      <state_interface name="effort"/>
    </joint>
    <joint name="right_joint_3">
      <command_interface name="effort"/>
      <state_interface name="position"/>
      <state_interface name="velocity"/>
      <state_interface name="effort"/>
    </joint>
    <joint name="right_joint_4">
      <command_interface name="effort"/>
      <state_interface name="position"/>
      <state_interface name="velocity"/>
      <state_interface name="effort"/>
    </joint>
    <joint name="right_joint_5">
      <command_interface name="effort"/>
      <state_interface name="position"/>
      <state_interface name="velocity"/>
      <state_interface name="effort"/>
    </joint>
    <joint name="right_joint_6">
      <command_interface name="effort"/>
      <state_interface name="position"/>
      <state_interface name="velocity"/>
      <state_interface name="effort"/>
    </joint>
    <joint name="left_gripper_right_finger_joint">
      <command_interface name="effort"/>
      <state_interface name="position"/>
      <state_interface name="velocity"/>
      <state_interface name="effort"/>
    </joint>
    <joint name="right_gripper_right_finger_joint">
      <command_interface name="effort"/>
      <state_interface name="position"/>
      <state_interface name="velocity"/>
      <state_interface name="effort"/>
    </joint>
  </ros2_control>
</robot>

