<?xml version="1.0" ?>
<!-- =================================================================================== -->
<!-- |    This document was autogenerated by xacro from dual_arm_robot.urdf.xacro      | -->
<!-- |    EDITING THIS FILE BY HAND IS NOT RECOMMENDED                                 | -->
<!-- =================================================================================== -->
<robot name="dual_arm_robot">
  <link name="base_footprint"/>
  <joint name="support_base_joint" type="fixed">
    <origin rpy="0 0 0" xyz="0 0 0"/>
    <parent link="base_footprint"/>
    <child link="base_link"/>
  </joint>
  <link name="base_link">
    <inertial>
      <origin rpy="0 0 0" xyz="4.4390908945955E-08 6.15097131842071E-08 0.625"/>
      <mass value="2.19423393695423"/>
      <inertia ixx="0.287192437664211" ixy="2.69040881704817E-09" ixz="9.91925905799376E-16" iyy="0.287192448392283" iyz="5.97292812641121E-20" izz="0.00296979830799831"/>
    </inertial>
    <visual>
      <origin rpy="0 0 0" xyz="0 0 0"/>
      <geometry>
        <mesh filename="package://dual_arm_support/meshes/base_link.STL"/>
      </geometry>
      <material name="">
        <color rgba="0.792156862745098 0.819607843137255 0.933333333333333 1"/>
      </material>
    </visual>
    <collision>
      <origin rpy="0 0 0" xyz="0 0 0"/>
      <geometry>
        <mesh filename="package://dual_arm_support/meshes/base_link.STL"/>
      </geometry>
    </collision>
  </link>
  <link name="left_arm_attachment_point">
    <inertial>
      <origin rpy="0 0 0" xyz="0.015 -4.7603E-17 0"/>
      <mass value="0.1018"/>
      <inertia ixx="5.7895E-05" ixy="-7.5643E-20" ixz="7.4422E-20" iyy="3.6583E-05" iyz="4.1359E-21" izz="3.6583E-05"/>
    </inertial>
    <visual>
      <origin rpy="0 0 0" xyz="0 0 0"/>
      <geometry>
        <mesh filename="package://dual_arm_support/meshes/left_arm_attachment_point.STL"/>
      </geometry>
      <material name="">
        <color rgba="0.79216 0.81961 0.93333 1"/>
      </material>
    </visual>
    <collision>
      <origin rpy="0 0 0" xyz="0 0 0"/>
      <geometry>
        <mesh filename="package://dual_arm_support/meshes/left_arm_attachment_point.STL"/>
      </geometry>
    </collision>
  </link>
  <joint name="left_arm_attachment_joint" type="fixed">
    <origin rpy="0 0 0" xyz="-0.07 0 1.12"/>
    <parent link="base_link"/>
    <child link="left_arm_attachment_point"/>
    <axis xyz="0 0 0"/>
  </joint>
  <link name="right_arm_attachment_point">
    <inertial>
      <origin rpy="0 0 0" xyz="-0.015 5.7142E-17 0"/>
      <mass value="0.1018"/>
      <inertia ixx="5.7895E-05" ixy="-7.5643E-20" ixz="7.4422E-20" iyy="3.6583E-05" iyz="3.3087E-21" izz="3.6583E-05"/>
    </inertial>
    <visual>
      <origin rpy="0 0 0" xyz="0 0 0"/>
      <geometry>
        <mesh filename="package://dual_arm_support/meshes/right_arm_attachment_point.STL"/>
      </geometry>
      <material name="">
        <color rgba="0.79216 0.81961 0.93333 1"/>
      </material>
    </visual>
    <collision>
      <origin rpy="0 0 0" xyz="0 0 0"/>
      <geometry>
        <mesh filename="package://dual_arm_support/meshes/right_arm_attachment_point.STL"/>
      </geometry>
    </collision>
  </link>
  <joint name="right_arm_attachment_joint" type="fixed">
    <origin rpy="0 0 0" xyz="0.07 0 1.12"/>
    <parent link="base_link"/>
    <child link="right_arm_attachment_point"/>
    <axis xyz="0 0 0"/>
  </joint>
  <joint name="left_arm_base_joint" type="fixed">
    <origin rpy="0 1.5708 3.1416" xyz="0 0 0"/>
    <parent link="left_arm_attachment_point"/>
    <child link="left_base_link"/>
  </joint>
  <link name="left_base_link">
    <inertial>
      <origin rpy="0 0 0" xyz="0.00017935 0.0018838 0.038665"/>
      <mass value="0.45399"/>
      <inertia ixx="0.00031392" ixy="5.1311E-09" ixz="6.0341E-09" iyy="0.00034489" iyz="-2.4366E-06" izz="0.00052725"/>
    </inertial>
    <visual>
      <origin rpy="0 0 0" xyz="0 0 0"/>
      <geometry>
        <mesh filename="package://left_arm_description/meshes/left_base_link.STL"/>
      </geometry>
      <material name="">
        <color rgba="0.79216 0.81961 0.93333 1"/>
      </material>
    </visual>
    <collision>
      <origin rpy="0 0 0" xyz="0 0 0"/>
      <geometry>
        <mesh filename="package://left_arm_description/meshes/left_base_link.STL"/>
      </geometry>
    </collision>
  </link>
  <link name="left_link_1">
    <inertial>
      <origin rpy="0 0 0" xyz="-0.00109529335918426 0.00158432100362189 -0.00494979473059115"/>
      <mass value="0.485026463246757"/>
      <inertia ixx="0.000324710887277216" ixy="-1.07713142915927E-08" ixz="-4.83157041007323E-06" iyy="0.00061925419676812" iyz="-9.71161354629019E-09" izz="0.000443684285755112"/>
    </inertial>
    <visual>
      <origin rpy="0 0 0" xyz="0 0 0"/>
      <geometry>
        <mesh filename="package://left_arm_description/meshes/left_link_1.STL"/>
      </geometry>
      <material name="">
        <color rgba="0.792156862745098 0.819607843137255 0.933333333333333 1"/>
      </material>
    </visual>
    <collision>
      <origin rpy="0 0 0" xyz="0 0 0"/>
      <geometry>
        <mesh filename="package://left_arm_description/meshes/left_link_1.STL"/>
      </geometry>
    </collision>
  </link>
  <joint name="left_joint_0" type="revolute">
    <origin rpy="0 0 0" xyz="0 0 0.1355"/>
    <parent link="left_base_link"/>
    <child link="left_link_1"/>
    <axis xyz="0 0 -1"/>
    <limit effort="40" lower="-2.3562" upper="2.8798" velocity="10.472"/>
    <dynamics damping="0.1" friction="0.1"/>
  </joint>
  <link name="left_link_2">
    <inertial>
      <origin rpy="0 0 0" xyz="0.000508224298191348 -0.0449280282138882 -0.0206256236163859"/>
      <mass value="0.0574247036424834"/>
      <inertia ixx="3.63772438524509E-05" ixy="-6.73097320771988E-08" ixz="2.4361029786039E-07" iyy="1.63998990434084E-05" iyz="8.38613176703722E-06" izz="3.40084027627687E-05"/>
    </inertial>
    <visual>
      <origin rpy="0 0 0" xyz="0 0 0"/>
      <geometry>
        <mesh filename="package://left_arm_description/meshes/left_link_2.STL"/>
      </geometry>
      <material name="">
        <color rgba="0.792156862745098 0.819607843137255 0.933333333333333 1"/>
      </material>
    </visual>
    <collision>
      <origin rpy="0 0 0" xyz="0 0 0"/>
      <geometry>
        <mesh filename="package://left_arm_description/meshes/left_link_2.STL"/>
      </geometry>
    </collision>
  </link>
  <joint name="left_joint_1" type="revolute">
    <origin rpy="1.5708 -1.5708 0" xyz="0 0 0"/>
    <parent link="left_link_1"/>
    <child link="left_link_2"/>
    <axis xyz="0 0 -1"/>
    <limit effort="40" lower="-3.0513" upper="0.3491" velocity="10.472"/>
    <dynamics damping="0.1" friction="0.1"/>
  </joint>
  <link name="left_link_3">
    <inertial>
      <origin rpy="0 0 0" xyz="2.83802482036803E-07 -0.000605505330037032 0.054984322701974"/>
      <mass value="0.347887365361116"/>
      <inertia ixx="0.00016909449015918" ixy="-5.64381355454147E-09" ixz="-3.74216751329525E-07" iyy="0.000190785450003569" iyz="6.28996978872466E-07" izz="0.0001501394093245"/>
    </inertial>
    <visual>
      <origin rpy="0 0 0" xyz="0 0 0"/>
      <geometry>
        <mesh filename="package://left_arm_description/meshes/left_link_3.STL"/>
      </geometry>
      <material name="">
        <color rgba="0.792156862745098 0.819607843137255 0.933333333333333 1"/>
      </material>
    </visual>
    <collision>
      <origin rpy="0 0 0" xyz="0 0 0"/>
      <geometry>
        <mesh filename="package://left_arm_description/meshes/left_link_3.STL"/>
      </geometry>
    </collision>
  </link>
  <joint name="left_joint_2" type="revolute">
    <origin rpy="0 1.5708 1.5708" xyz="0 -0.20975 0"/>
    <parent link="left_link_2"/>
    <child link="left_link_3"/>
    <axis xyz="0 0 -1"/>
    <limit effort="27" lower="-2.5307" upper="2.5307" velocity="3.77"/>
    <dynamics damping="0.1" friction="0.1"/>
  </joint>
  <link name="left_link_4">
    <inertial>
      <origin rpy="0 0 0" xyz="0.000110401234317883 -0.0670069142247546 0.000940172282106119"/>
      <mass value="0.192196245053756"/>
      <inertia ixx="0.000139241634507352" ixy="-1.09514406858182E-07" ixz="4.86638971490442E-08" iyy="7.39315447647571E-05" iyz="-1.40102816712551E-06" izz="0.000152967351058858"/>
    </inertial>
    <visual>
      <origin rpy="0 0 0" xyz="0 0 0"/>
      <geometry>
        <mesh filename="package://left_arm_description/meshes/left_link_4.STL"/>
      </geometry>
      <material name="">
        <color rgba="0.792156862745098 0.819607843137255 0.933333333333333 1"/>
      </material>
    </visual>
    <collision>
      <origin rpy="0 0 0" xyz="0 0 0"/>
      <geometry>
        <mesh filename="package://left_arm_description/meshes/left_link_4.STL"/>
      </geometry>
    </collision>
  </link>
  <joint name="leftt_joint_3" type="revolute">
    <origin rpy="1.5708 0 0" xyz="0 0 0"/>
    <parent link="left_link_3"/>
    <child link="left_link_4"/>
    <axis xyz="0 0 1"/>
    <limit effort="27" lower="-2.0944" upper="1.4835" velocity="3.77"/>
    <dynamics damping="0.1" friction="0.1"/>
  </joint>
  <link name="left_link_5">
    <inertial>
      <origin rpy="0 0 0" xyz="0.000305709664333387 0.00111778275538414 0.08453196488493"/>
      <mass value="0.229104472480576"/>
      <inertia ixx="0.000128732031959257" ixy="-3.70084067657107E-08" ixz="-2.59853293405133E-07" iyy="0.000171889502783524" iyz="8.03035899395303E-07" izz="8.33795545006523E-05"/>
    </inertial>
    <visual>
      <origin rpy="0 0 0" xyz="0 0 0"/>
      <geometry>
        <mesh filename="package://left_arm_description/meshes/left_link_5.STL"/>
      </geometry>
      <material name="">
        <color rgba="0.792156862745098 0.819607843137255 0.933333333333333 1"/>
      </material>
    </visual>
    <collision>
      <origin rpy="0 0 0" xyz="0 0 0"/>
      <geometry>
        <mesh filename="package://left_arm_description/meshes/left_link_5.STL"/>
      </geometry>
    </collision>
  </link>
  <joint name="left_joint_4" type="revolute">
    <origin rpy="-1.5707963267949 0 0" xyz="0 -0.24 0"/>
    <parent link="left_link_4"/>
    <child link="left_link_5"/>
    <axis xyz="0 0 -1"/>
    <limit effort="12.5" lower="-2.5307" upper="2.5307" velocity="12.566"/>
    <dynamics damping="0.1" friction="0.1"/>
  </joint>
  <link name="left_link_6">
    <inertial>
      <origin rpy="0 0 0" xyz="-0.00109259369146801 -0.000479735518615576 -0.000148198512131464"/>
      <mass value="0.139362135042712"/>
      <inertia ixx="6.4960146424318E-05" ixy="-1.55655636897026E-08" ixz="2.59648147811274E-07" iyy="4.7353477251241E-05" iyz="2.71283714204269E-08" izz="4.56210094444337E-05"/>
    </inertial>
    <visual>
      <origin rpy="0 0 0" xyz="0 0 0"/>
      <geometry>
        <mesh filename="package://left_arm_description/meshes/left_link_6.STL"/>
      </geometry>
      <material name="">
        <color rgba="0.792156862745098 0.819607843137255 0.933333333333333 1"/>
      </material>
    </visual>
    <collision>
      <origin rpy="0 0 0" xyz="0 0 0"/>
      <geometry>
        <mesh filename="package://left_arm_description/meshes/left_link_6.STL"/>
      </geometry>
    </collision>
  </link>
  <joint name="left_joint_5" type="revolute">
    <origin rpy="1.5708 0 0" xyz="0 0 0"/>
    <parent link="left_link_5"/>
    <child link="left_link_6"/>
    <axis xyz="0 0 1"/>
    <limit effort="12.5" lower="-0.6981" upper="0.6981" velocity="12.566"/>
    <dynamics damping="0.1" friction="0.1"/>
  </joint>
  <link name="left_link_7">
    <inertial>
      <origin rpy="0 0 0" xyz="0.0286842428588672 6.10622663543836E-16 0.00370678756780378"/>
      <mass value="0.0645715321756567"/>
      <inertia ixx="1.6246823902003E-05" ixy="-6.3863403085144E-20" ixz="2.30554210826466E-08" iyy="2.08555321432597E-05" iyz="4.85971131965754E-21" izz="1.97081566842342E-05"/>
    </inertial>
    <visual>
      <origin rpy="0 0 0" xyz="0 0 0"/>
      <geometry>
        <mesh filename="package://left_arm_description/meshes/left_link_7.STL"/>
      </geometry>
      <material name="">
        <color rgba="0.792156862745098 0.819607843137255 0.933333333333333 1"/>
      </material>
    </visual>
    <collision>
      <origin rpy="0 0 0" xyz="0 0 0"/>
      <geometry>
        <mesh filename="package://left_arm_description/meshes/left_link_7.STL"/>
      </geometry>
    </collision>
  </link>
  <joint name="left_joint_6" type="revolute">
    <origin rpy="1.5708 0 -1.5708" xyz="0 0 0"/>
    <parent link="left_link_6"/>
    <child link="left_link_7"/>
    <axis xyz="0 0 -1"/>
    <limit effort="12.5" lower="-1.5708" upper="1.5708" velocity="12.566"/>
    <dynamics damping="0.1" friction="0.1"/>
  </joint>
  <link name="left_attachment_point"/>
  <joint name="left_attachment_fixed_joint" type="fixed">
    <origin rpy="1.5708 0 1.5708" xyz="0.06 0 0"/>
    <parent link="left_link_7"/>
    <child link="left_attachment_point"/>
  </joint>
  <joint name="right_arm_base_joint" type="fixed">
    <origin rpy="0 1.5708 0" xyz="0 0 0"/>
    <parent link="right_arm_attachment_point"/>
    <child link="right_base_link"/>
  </joint>
  <link name="right_base_link">
    <inertial>
      <origin rpy="0 0 0" xyz="0.00017935 -0.0018838 0.038665"/>
      <mass value="0.45399"/>
      <inertia ixx="0.00031392" ixy="-5.1307E-09" ixz="6.0341E-09" iyy="0.00034489" iyz="2.4366E-06" izz="0.00052725"/>
    </inertial>
    <visual>
      <origin rpy="0 0 0" xyz="0 0 0"/>
      <geometry>
        <mesh filename="package://right_arm_description/meshes/right_base_link.STL"/>
      </geometry>
      <material name="">
        <color rgba="0.79216 0.81961 0.93333 1"/>
      </material>
    </visual>
    <collision>
      <origin rpy="0 0 0" xyz="0 0 0"/>
      <geometry>
        <mesh filename="package://right_arm_description/meshes/right_base_link.STL"/>
      </geometry>
    </collision>
  </link>
  <link name="right_link_1">
    <inertial>
      <origin rpy="0 0 0" xyz="-0.0010955 -0.0015843 -0.0049495"/>
      <mass value="0.48503"/>
      <inertia ixx="0.00032471" ixy="1.1251E-08" ixz="-4.8339E-06" iyy="0.00061927" iyz="9.6824E-09" izz="0.0004437"/>
    </inertial>
    <visual>
      <origin rpy="0 0 3.1416" xyz="0 0 0"/>
      <geometry>
        <mesh filename="package://right_arm_description/meshes/right_link_1.STL"/>
      </geometry>
      <material name="">
        <color rgba="0.79216 0.81961 0.93333 1"/>
      </material>
    </visual>
    <collision>
      <origin rpy="0 0 0" xyz="0 0 0"/>
      <geometry>
        <mesh filename="package://right_arm_description/meshes/right_link_1.STL"/>
      </geometry>
    </collision>
  </link>
  <joint name="right_joint_0" type="revolute">
    <origin rpy="0 0 3.1416" xyz="0 0 0.1355"/>
    <parent link="right_base_link"/>
    <child link="right_link_1"/>
    <axis xyz="0 0 -1"/>
    <limit effort="40" lower="-2.8798" upper="2.3562" velocity="10.472"/>
    <dynamics damping="0.1" friction="0.1"/>
  </joint>
  <link name="right_link_2">
    <inertial>
      <origin rpy="0 0 0" xyz="0.00050822 0.044928 -0.020626"/>
      <mass value="0.057425"/>
      <inertia ixx="3.6377E-05" ixy="6.731E-08" ixz="2.4361E-07" iyy="1.64E-05" iyz="-8.3861E-06" izz="3.4008E-05"/>
    </inertial>
    <visual>
      <origin rpy="0 0 0" xyz="0 0 0"/>
      <geometry>
        <mesh filename="package://right_arm_description/meshes/right_link_2.STL"/>
      </geometry>
      <material name="">
        <color rgba="0.79216 0.81961 0.93333 1"/>
      </material>
    </visual>
    <collision>
      <origin rpy="0 0 0" xyz="0 0 0"/>
      <geometry>
        <mesh filename="package://right_arm_description/meshes/right_link_2.STL"/>
      </geometry>
    </collision>
  </link>
  <joint name="right_joint_1" type="revolute">
    <origin rpy="1.5708 -1.5708 0" xyz="0 0 0"/>
    <parent link="right_link_1"/>
    <child link="right_link_2"/>
    <axis xyz="0 0 -1"/>
    <limit effort="40" lower="-0.3491" upper="3.0543" velocity="10.472"/>
    <dynamics damping="0.1" friction="0.1"/>
  </joint>
  <link name="right_link_3">
    <inertial>
      <origin rpy="0 0 0" xyz="3.1902E-07 0.00060542 0.054984"/>
      <mass value="0.34789"/>
      <inertia ixx="0.00016909" ixy="5.4859E-09" ixz="-3.7432E-07" iyy="0.00019078" iyz="-6.287E-07" izz="0.00015014"/>
    </inertial>
    <visual>
      <origin rpy="0 0 0" xyz="0 0 0"/>
      <geometry>
        <mesh filename="package://right_arm_description/meshes/right_link_3.STL"/>
      </geometry>
      <material name="">
        <color rgba="0.79216 0.81961 0.93333 1"/>
      </material>
    </visual>
    <collision>
      <origin rpy="0 0 0" xyz="0 0 0"/>
      <geometry>
        <mesh filename="package://right_arm_description/meshes/right_link_3.STL"/>
      </geometry>
    </collision>
  </link>
  <joint name="right_joint_2" type="revolute">
    <origin rpy="1.5708 1.5708 0" xyz="0 0.20975 0"/>
    <parent link="right_link_2"/>
    <child link="right_link_3"/>
    <axis xyz="0 0 -1"/>
    <limit effort="27" lower="-2.5307" upper="2.5307" velocity="3.7699"/>
    <dynamics damping="0.1" friction="0.1"/>
  </joint>
  <link name="right_link_4">
    <inertial>
      <origin rpy="0 0 0" xyz="0.0001104 0.067007 0.00094041"/>
      <mass value="0.1922"/>
      <inertia ixx="0.00013924" ixy="1.098E-07" ixz="4.8806E-08" iyy="7.3932E-05" iyz="1.401E-06" izz="0.00015297"/>
    </inertial>
    <visual>
      <origin rpy="0 0 0" xyz="0 0 0"/>
      <geometry>
        <mesh filename="package://right_arm_description/meshes/right_link_4.STL"/>
      </geometry>
      <material name="">
        <color rgba="0.79216 0.81961 0.93333 1"/>
      </material>
    </visual>
    <collision>
      <origin rpy="0 0 0" xyz="0 0 0"/>
      <geometry>
        <mesh filename="package://right_arm_description/meshes/right_link_4.STL"/>
      </geometry>
    </collision>
  </link>
  <joint name="right_joint_3" type="revolute">
    <origin rpy="-1.5708 0 0" xyz="0 0 0"/>
    <parent link="right_link_3"/>
    <child link="right_link_4"/>
    <axis xyz="0 0 -1"/>
    <limit effort="27" lower="-2.0944" upper="1.5708" velocity="3.7699"/>
    <dynamics damping="0.1" friction="0.1"/>
  </joint>
  <link name="right_link_5">
    <inertial>
      <origin rpy="0 0 0" xyz="0.00030568 -0.0011178 0.084532"/>
      <mass value="0.2291"/>
      <inertia ixx="0.00012873" ixy="3.6981E-08" ixz="-2.6007E-07" iyy="0.00017189" iyz="-8.0305E-07" izz="8.3379E-05"/>
    </inertial>
    <visual>
      <origin rpy="0 0 0" xyz="0 0 0"/>
      <geometry>
        <mesh filename="package://right_arm_description/meshes/right_link_5.STL"/>
      </geometry>
      <material name="">
        <color rgba="0.79216 0.81961 0.93333 1"/>
      </material>
    </visual>
    <collision>
      <origin rpy="0 0 0" xyz="0 0 0"/>
      <geometry>
        <mesh filename="package://right_arm_description/meshes/right_link_5.STL"/>
      </geometry>
    </collision>
  </link>
  <joint name="right_joint_4" type="revolute">
    <origin rpy="1.5708 0 0" xyz="0 0.24 0"/>
    <parent link="right_link_4"/>
    <child link="right_link_5"/>
    <axis xyz="0 0 -1"/>
    <limit effort="7" lower="-2.5307" upper="2.5307" velocity="12.566"/>
    <dynamics damping="0.1" friction="0.1"/>
  </joint>
  <link name="right_link_6">
    <inertial>
      <origin rpy="0 0 0" xyz="0.0010926 -0.00047974 -0.0001482"/>
      <mass value="0.13936"/>
      <inertia ixx="6.496E-05" ixy="1.5574E-08" ixz="-2.5967E-07" iyy="4.7354E-05" iyz="2.7157E-08" izz="4.5621E-05"/>
    </inertial>
    <visual>
      <origin rpy="0 0 0" xyz="0 0 0"/>
      <geometry>
        <mesh filename="package://right_arm_description/meshes/right_link_6.STL"/>
      </geometry>
      <material name="">
        <color rgba="0.79216 0.81961 0.93333 1"/>
      </material>
    </visual>
    <collision>
      <origin rpy="0 0 0" xyz="0 0 0"/>
      <geometry>
        <mesh filename="package://right_arm_description/meshes/right_link_6.STL"/>
      </geometry>
    </collision>
  </link>
  <joint name="right_joint_5" type="revolute">
    <origin rpy="1.5708 0 3.1416" xyz="0 0 0"/>
    <parent link="right_link_5"/>
    <child link="right_link_6"/>
    <axis xyz="0 0 -1"/>
    <limit effort="7" lower="-0.6981" upper="0.6981" velocity="12.566"/>
    <dynamics damping="0.1" friction="0.1"/>
  </joint>
  <link name="right_link_7">
    <inertial>
      <origin rpy="0 0 0" xyz="-5.5511E-17 0.028684 0.0037068"/>
      <mass value="0.064572"/>
      <inertia ixx="2.0856E-05" ixy="-7.2505E-20" ixz="9.9893E-20" iyy="1.6247E-05" iyz="2.3055E-08" izz="1.9708E-05"/>
    </inertial>
    <visual>
      <origin rpy="0 0 0" xyz="0 0 0"/>
      <geometry>
        <mesh filename="package://right_arm_description/meshes/right_link_7.STL"/>
      </geometry>
      <material name="">
        <color rgba="0.79216 0.81961 0.93333 1"/>
      </material>
    </visual>
    <collision>
      <origin rpy="0 0 0" xyz="0 0 0"/>
      <geometry>
        <mesh filename="package://right_arm_description/meshes/right_link_7.STL"/>
      </geometry>
    </collision>
  </link>
  <joint name="right_joint_6" type="revolute">
    <origin rpy="0 -1.5708 -3.1416" xyz="0 0 0"/>
    <parent link="right_link_6"/>
    <child link="right_link_7"/>
    <axis xyz="0 0 -1"/>
    <limit effort="7" lower="-1.5708" upper="1.5708" velocity="12.566"/>
    <dynamics damping="0.1" friction="0.1"/>
  </joint>
  <link name="right_attachment_point"/>
  <joint name="right_attachment_fixed_joint" type="fixed">
    <origin rpy="-1.5708 -3.1416 0" xyz="0 0.06 0"/>
    <parent link="right_link_7"/>
    <child link="right_attachment_point"/>
  </joint>
  <joint name="left_gripper_gripper_base_joint" type="fixed">
    <origin rpy="0 0 0" xyz="0 0 0"/>
    <parent link="left_attachment_point"/>
    <child link="left_gripper_gripper_base_link"/>
  </joint>
  <link name="left_gripper_gripper_base_link">
    <inertial>
      <origin rpy="0 0 0" xyz="1.1802E-06 6.1128E-05 0.030778"/>
      <mass value="0.13427"/>
      <inertia ixx="3.2989E-05" ixy="6.6347E-08" ixz="-5.3189E-10" iyy="6.393E-05" iyz="4.1834E-08" izz="7.8294E-05"/>
    </inertial>
    <visual>
      <origin rpy="0 0 0" xyz="0 0 0"/>
      <geometry>
        <mesh filename="package://gripper_description/meshes/gripper_base_link.STL"/>
      </geometry>
      <material name="">
        <color rgba="0.79216 0.81961 0.93333 1"/>
      </material>
    </visual>
    <collision>
      <origin rpy="0 0 0" xyz="0 0 0"/>
      <geometry>
        <mesh filename="package://gripper_description/meshes/gripper_base_link.STL"/>
      </geometry>
    </collision>
  </link>
  <link name="left_gripper_right_finger">
    <inertial>
      <origin rpy="0 0 0" xyz="0.0034569 0.0014257 -0.003385"/>
      <mass value="0.045391"/>
      <inertia ixx="1.0348E-05" ixy="-5.9266E-09" ixz="-1.3649E-06" iyy="1.4034E-05" iyz="1.0436E-07" izz="1.3172E-05"/>
    </inertial>
    <visual>
      <origin rpy="0 0 0" xyz="0 0 0"/>
      <geometry>
        <mesh filename="package://gripper_description/meshes/right_finger.STL"/>
      </geometry>
      <material name="">
        <color rgba="0.79216 0.81961 0.93333 1"/>
      </material>
    </visual>
    <collision>
      <origin rpy="0 0 0" xyz="0 0 0"/>
      <geometry>
        <mesh filename="package://gripper_description/meshes/right_finger.STL"/>
      </geometry>
    </collision>
  </link>
  <joint name="left_gripper_right_finger_joint" type="prismatic">
    <origin rpy="0 0 0" xyz="-0.065 0 0.079"/>
    <parent link="left_gripper_gripper_base_link"/>
    <child link="left_gripper_right_finger"/>
    <axis xyz="1 0 0"/>
    <limit effort="80" lower="0" upper="0.045" velocity="0.125"/>
    <dynamics damping="0.1" friction="0.1"/>
  </joint>
  <link name="left_gripper_left_finger">
    <inertial>
      <origin rpy="0 0 0" xyz="-0.0034569 -0.0014257 -0.003385"/>
      <mass value="0.045391"/>
      <inertia ixx="1.0348E-05" ixy="-5.9266E-09" ixz="1.3649E-06" iyy="1.4034E-05" iyz="-1.0436E-07" izz="1.3172E-05"/>
    </inertial>
    <visual>
      <origin rpy="0 0 0" xyz="0 0 0"/>
      <geometry>
        <mesh filename="package://gripper_description/meshes/left_finger.STL"/>
      </geometry>
      <material name="">
        <color rgba="0.79216 0.81961 0.93333 1"/>
      </material>
    </visual>
    <collision>
      <origin rpy="0 0 0" xyz="0 0 0"/>
      <geometry>
        <mesh filename="package://gripper_description/meshes/left_finger.STL"/>
      </geometry>
    </collision>
  </link>
  <joint name="left_gripper_left_finger_joint" type="prismatic">
    <origin rpy="0 0 0" xyz="0.065 0 0.079"/>
    <parent link="left_gripper_gripper_base_link"/>
    <child link="left_gripper_left_finger"/>
    <axis xyz="-1 0 0"/>
    <limit effort="80" lower="0" upper="0.045" velocity="0.125"/>
    <dynamics damping="0.1" friction="0.1"/>
    <mimic joint="left_gripper_right_finger_joint" multiplier="1" offset="0"/>
  </joint>
  <joint name="right_gripper_gripper_base_joint" type="fixed">
    <origin rpy="0 0 0" xyz="0 0 0"/>
    <parent link="right_attachment_point"/>
    <child link="right_gripper_gripper_base_link"/>
  </joint>
  <link name="right_gripper_gripper_base_link">
    <inertial>
      <origin rpy="0 0 0" xyz="1.1802E-06 6.1128E-05 0.030778"/>
      <mass value="0.13427"/>
      <inertia ixx="3.2989E-05" ixy="6.6347E-08" ixz="-5.3189E-10" iyy="6.393E-05" iyz="4.1834E-08" izz="7.8294E-05"/>
    </inertial>
    <visual>
      <origin rpy="0 0 0" xyz="0 0 0"/>
      <geometry>
        <mesh filename="package://gripper_description/meshes/gripper_base_link.STL"/>
      </geometry>
      <material name="">
        <color rgba="0.79216 0.81961 0.93333 1"/>
      </material>
    </visual>
    <collision>
      <origin rpy="0 0 0" xyz="0 0 0"/>
      <geometry>
        <mesh filename="package://gripper_description/meshes/gripper_base_link.STL"/>
      </geometry>
    </collision>
  </link>
  <link name="right_gripper_right_finger">
    <inertial>
      <origin rpy="0 0 0" xyz="0.0034569 0.0014257 -0.003385"/>
      <mass value="0.045391"/>
      <inertia ixx="1.0348E-05" ixy="-5.9266E-09" ixz="-1.3649E-06" iyy="1.4034E-05" iyz="1.0436E-07" izz="1.3172E-05"/>
    </inertial>
    <visual>
      <origin rpy="0 0 0" xyz="0 0 0"/>
      <geometry>
        <mesh filename="package://gripper_description/meshes/right_finger.STL"/>
      </geometry>
      <material name="">
        <color rgba="0.79216 0.81961 0.93333 1"/>
      </material>
    </visual>
    <collision>
      <origin rpy="0 0 0" xyz="0 0 0"/>
      <geometry>
        <mesh filename="package://gripper_description/meshes/right_finger.STL"/>
      </geometry>
    </collision>
  </link>
  <joint name="right_gripper_right_finger_joint" type="prismatic">
    <origin rpy="0 0 0" xyz="-0.065 0 0.079"/>
    <parent link="right_gripper_gripper_base_link"/>
    <child link="right_gripper_right_finger"/>
    <axis xyz="1 0 0"/>
    <limit effort="80" lower="0" upper="0.045" velocity="0.125"/>
    <dynamics damping="0.1" friction="0.1"/>
  </joint>
  <link name="right_gripper_left_finger">
    <inertial>
      <origin rpy="0 0 0" xyz="-0.0034569 -0.0014257 -0.003385"/>
      <mass value="0.045391"/>
      <inertia ixx="1.0348E-05" ixy="-5.9266E-09" ixz="1.3649E-06" iyy="1.4034E-05" iyz="-1.0436E-07" izz="1.3172E-05"/>
    </inertial>
    <visual>
      <origin rpy="0 0 0" xyz="0 0 0"/>
      <geometry>
        <mesh filename="package://gripper_description/meshes/left_finger.STL"/>
      </geometry>
      <material name="">
        <color rgba="0.79216 0.81961 0.93333 1"/>
      </material>
    </visual>
    <collision>
      <origin rpy="0 0 0" xyz="0 0 0"/>
      <geometry>
        <mesh filename="package://gripper_description/meshes/left_finger.STL"/>
      </geometry>
    </collision>
  </link>
  <joint name="right_gripper_left_finger_joint" type="prismatic">
    <origin rpy="0 0 0" xyz="0.065 0 0.079"/>
    <parent link="right_gripper_gripper_base_link"/>
    <child link="right_gripper_left_finger"/>
    <axis xyz="-1 0 0"/>
    <limit effort="80" lower="0" upper="0.045" velocity="0.125"/>
    <dynamics damping="0.1" friction="0.1"/>
    <mimic joint="right_gripper_right_finger_joint" multiplier="1" offset="0"/>
  </joint>
</robot>
